<mujoco model="arm_hand">
  <compiler angle="radian" meshdir="../assets/robotis_ffw/assets" autolimits="true"/>

  <option timestep="0.001" integrator="implicitfast" cone="elliptic" impratio="10"/>

  <visual>
    <headlight diffuse="0.6 0.6 0.6" ambient="0.3 0.3 0.3" specular="0 0 0"/>
    <rgba haze="0.15 0.25 0.35 1"/>
    <global azimuth="120" elevation="-20" offwidth="1280" offheight="960"/>
  </visual>

  <asset>
    <texture type="skybox" builtin="gradient" rgb1="0.3 0.5 0.7" rgb2="0 0 0" width="512" height="3072"/>
    <texture type="2d" name="groundplane" builtin="checker" mark="edge" rgb1="0.2 0.3 0.4" rgb2="0.1 0.2 0.3"
      markrgb="0.8 0.8 0.8" width="300" height="300"/>
    <material name="groundplane" texture="groundplane" texuniform="true" texrepeat="5 5" reflectance="0.2"/>
    <material name="black" rgba="0.2 0.2 0.2 1"/>
    <material name="table_mat" rgba="0.55 0.4 0.3 1"/>
    <material name="can_mat" rgba="0.75 0.1 0.1 1"/>

    <mesh name="arm_r_link1" file="ffw_s/arm_r_link1.stl" scale="0.001 0.001 0.001"/>
    <mesh name="arm_r_link2" file="ffw_s/arm_r_link2.stl" scale="0.001 0.001 0.001"/>
    <mesh name="arm_r_link3" file="ffw_s/arm_r_link3.stl" scale="0.001 0.001 0.001"/>
    <mesh name="arm_r_link4" file="ffw_s/arm_r_link4.stl" scale="0.001 0.001 0.001"/>
    <mesh name="arm_r_link5" file="ffw_s/arm_r_link5.stl" scale="0.001 0.001 0.001"/>
    <mesh name="arm_r_link6" file="ffw_s/arm_r_link6.stl" scale="0.001 0.001 0.001"/>
    <mesh name="arm_r_link7" file="ffw_s/arm_r_link7.stl" scale="0.001 0.001 0.001"/>

    <mesh name="hx5_r_base" file="hx5_d20/hx5_d20_right/hx5_d20_base_unit.stl" scale="0.001 0.001 0.001"/>
    <mesh name="hx5_r_thumb_mcp" file="hx5_d20/hx5_d20_right/hx5_d20_thumb_mcp.stl" scale="0.001 0.001 0.001"/>
    <mesh name="hx5_r_thumb_mcp2" file="hx5_d20/hx5_d20_right/hx5_d20_thumb_mcp2.stl" scale="0.001 0.001 0.001"/>
    <mesh name="hx5_r_thumb_ip" file="hx5_d20/hx5_d20_right/hx5_d20_thumb_ip.stl" scale="0.001 0.001 0.001"/>
    <mesh name="hx5_r_thumb_tip" file="hx5_d20/hx5_d20_right/hx5_d20_thumb_tip.stl" scale="0.001 0.001 0.001"/>
    <mesh name="hx5_r_finger_mcp" file="hx5_d20/hx5_d20_right/hx5_d20_finger_mcp.stl" scale="0.001 0.001 0.001"/>
    <mesh name="hx5_r_finger_pip" file="hx5_d20/hx5_d20_right/hx5_d20_finger_pip.stl" scale="0.001 0.001 0.001"/>
    <mesh name="hx5_r_finger_dip" file="hx5_d20/hx5_d20_right/hx5_d20_finger_dip.stl" scale="0.001 0.001 0.001"/>
    <mesh name="hx5_r_finger_tip" file="hx5_d20/hx5_d20_right/hx5_d20_finger_tip.stl" scale="0.001 0.001 0.001"/>
  </asset>

  <default>
    <default class="visual">
      <geom type="mesh" contype="0" conaffinity="0" density="0" group="2"/>
    </default>
    <!-- Arm links: plain mesh collision (self-collision fidelity isn't this phase's focus) -->
    <default class="arm_collision">
      <geom type="mesh" group="3"/>
    </default>
    <!-- Hand collision: shadow_hand recipe, identical to models/hand_only.xml (Phase 1/2) -->
    <default class="collision">
      <geom group="3" contype="1" conaffinity="1" condim="3" solimp="0.5 0.99 0.0001" solref="0.005 1"/>
    </default>

    <!-- DY-80 motor: arm joint 1, 2 -->
    <default class="DY_80">
      <joint frictionloss="0.1" armature="0.5" damping="30.0"/>
      <position kp="600" dampratio="1" forcerange="-61.4 61.4"/>
      <default class="arm_r_joint1">
        <joint axis="0 1 0" range="-3.14 3.14"/>
      </default>
      <default class="arm_r_joint2">
        <joint axis="1 0 0" range="-3.14 0"/>
      </default>
    </default>
    <!-- DY-70 motor: arm joint 3, 4, 5, 6 -->
    <default class="DY_70">
      <joint frictionloss="0.1" armature="0.5" damping="20.0"/>
      <position kp="600" dampratio="1" forcerange="-31.7 31.7"/>
      <default class="arm_r_joint3">
        <joint axis="0 0 1" range="-3.14 3.14"/>
      </default>
      <default class="arm_r_joint4">
        <joint axis="0 1 0" range="-2.9361 1.0786"/>
      </default>
      <default class="arm_r_joint5">
        <joint axis="0 0 1" range="-3.14 3.14"/>
      </default>
      <default class="arm_r_joint6">
        <joint axis="0 1 0" range="-1.57 1.57"/>
      </default>
    </default>
    <!-- DP-42 motor: arm joint 7 -->
    <default class="DP_42">
      <joint frictionloss="0.1" armature="0.1" damping="3.0"/>
      <position kp="200" dampratio="1" forcerange="-5.1 5.1"/>
      <default class="arm_r_joint7">
        <joint axis="1 0 0" range="-1.5804 1.8201"/>
      </default>
    </default>

    <!-- HX5-D20 5-finger hand (identical to models/hand_only.xml) -->
    <default class="finger">
      <joint frictionloss="0.05" armature="0.05" damping="1.0"/>
      <position kp="0.7" dampratio="1" forcerange="-1.0 1.0"/>
      <default class="thumb_r_cmc">
        <joint axis="1 0 0" range="-1.5708 1.5708"/>
      </default>
      <default class="thumb_r_mcp_yaw">
        <joint axis="0 0 1" range="-3.1416 0"/>
      </default>
      <default class="thumb_r_mcp_pitch">
        <joint axis="1 0 0" range="0 1.5708"/>
      </default>
      <default class="thumb_r_ip">
        <joint axis="1 0 0" range="0 1.5708"/>
      </default>
      <default class="finger_mcp">
        <joint axis="1 0 0" range="-0.6109 0.6109"/>
      </default>
      <default class="finger_pip">
        <joint axis="0 1 0" range="0 2.0071"/>
      </default>
      <default class="finger_dip">
        <joint axis="0 1 0" range="0 1.5708"/>
      </default>
      <default class="finger_tip">
        <joint axis="0 1 0" range="0 1.5708"/>
      </default>
    </default>
  </default>

  <worldbody>
    <light pos="0 0 2.2" dir="0 0 -1" directional="true"/>
    <geom name="floor" size="0 0 0.05" type="plane" material="groundplane"/>

    <!-- Table: top surface at z=0.65 (per PLAN.md) -->
    <!-- Narrow along X (arm-facing direction): the validated Phase 1/2 grasp geometry
         needs the palm to dip below the fingertip/can height on its near side (the palm
         sits "behind" the grasp point in this hand orientation) -- a full-width table
         collided with the palm every time it reached down (see NOTES.md "Phase 3"). Still
         wide enough in Y and deep enough under the can to look and behave like a table. -->
    <geom name="table" type="box" size="0.08 0.15 0.05" pos="0.5 0.0 0.60" material="table_mat"/>

    <!-- Can resting on the table (freejoint -- it always settles to table_top + its own
         half-height = 0.705 regardless of spawn height, so "floating" it here wouldn't
         work; the table-clearance fix lives in tests/test_phase_3.py's
         GRASP_TARGET_OFFSET instead, which aims the IK target 3cm above the can's actual
         resting center -- see NOTES.md "Phase 3"). -->
    <body name="can" pos="0.5 0.0 0.705">
      <freejoint name="can_free"/>
      <inertial pos="0 0 0" mass="0.35" diaginertia="0.000448 0.000448 0.00019"/>
      <geom name="can_geom" type="cylinder" size="0.033 0.055" material="can_mat"
        priority="1" condim="6" friction="0.5 0.01 0.003"
        solimp="0.5 0.99 0.0001" solref="0.005 1"/>
    </body>

    <!-- Right arm: base rigidly fixed to world at ~1.0m (approximate FFW-SH5 shoulder
         height per PLAN.md) -- mobile base and lift column are out of scope for this
         project, see PLAN.md Phase 4 (full_scene freezes the base too). -->
    <body name="arm_base_link" pos="0 0 1.0">
      <geom type="box" size="0.06 0.06 0.06" rgba="0.2 0.2 0.2 1"/>

      <body name="arm_r_link1" pos="0 -0.1045 0">
        <inertial pos="0.0162454 -0.115083 -0.000116015" quat="0.212043 0.665609 -0.229062 0.677889" mass="1.93395"
          diaginertia="0.00305635 0.00275332 0.00221466"/>
        <joint name="arm_r_joint1" class="arm_r_joint1"/>
        <geom mesh="arm_r_link1" material="black" class="visual"/>
        <geom mesh="arm_r_link1" class="arm_collision"/>

        <body name="arm_r_link2" pos="0 -0.123 0">
          <inertial pos="0.00904096 0.000105802 -0.144033" quat="0.707129 0.105833 0.108702 0.690617" mass="2.12414"
            diaginertia="0.0108559 0.0106863 0.00242145"/>
          <joint name="arm_r_joint2" class="arm_r_joint2"/>
          <geom mesh="arm_r_link2" material="black" class="visual"/>
          <geom mesh="arm_r_link2" class="arm_collision"/>

          <body name="arm_r_link3" pos="0 0 -0.165">
            <inertial pos="-2.51092e-05 -0.0179472 -0.108765" quat="0.447823 0.894113 0.00400928 -0.000680335" mass="1.40774"
              diaginertia="0.00193273 0.0017314 0.00128994"/>
            <joint name="arm_r_joint3" class="arm_r_joint3"/>
            <geom mesh="arm_r_link3" material="black" class="visual"/>
            <geom mesh="arm_r_link3" class="arm_collision"/>

            <body name="arm_r_link4" pos="0.041004 0 -0.135">
              <inertial pos="4.39703e-05 -0.00978736 -0.137888" quat="0.984402 0.175809 0.00125565 -0.00649329" mass="1.51314"
                diaginertia="0.00636295 0.00628021 0.00133398"/>
              <joint name="arm_r_joint4" class="arm_r_joint4"/>
              <geom mesh="arm_r_link4" material="black" class="visual"/>
              <geom mesh="arm_r_link4" class="arm_collision"/>

              <body name="arm_r_link5" pos="-0.041004 0 -0.1489">
                <inertial pos="-2.62962e-05 -0.0187957 -0.0983871" quat="0.546043 0.837751 0.00318354 -0.000761107" mass="1.34419"
                  diaginertia="0.00169762 0.00156986 0.00116911"/>
                <joint name="arm_r_joint5" class="arm_r_joint5"/>
                <geom mesh="arm_r_link5" material="black" class="visual"/>
                <geom mesh="arm_r_link5" class="arm_collision"/>

                <body name="arm_r_link6" pos="0 0 -0.1041">
                  <inertial pos="0.000339839 -0.0194304 -0.0639459" quat="0.662489 0.249825 -0.2542 0.658846" mass="0.636234"
                    diaginertia="0.00155564 0.00138901 0.000496769"/>
                  <joint name="arm_r_joint6" class="arm_r_joint6"/>
                  <geom mesh="arm_r_link6" material="black" class="visual"/>
                  <geom mesh="arm_r_link6" class="arm_collision"/>

                  <body name="arm_r_link7" pos="0 0 -0.0885">
                    <inertial pos="-0.00242011 -0.00201564 -0.0911446" quat="0.703942 -0.0528198 -0.0236914 0.707894" mass="0.384359"
                      diaginertia="0.00125471 0.0011001 0.000310982"/>
                    <joint name="arm_r_joint7" class="arm_r_joint7"/>
                    <geom mesh="arm_r_link7" material="black" class="visual"/>
                    <geom mesh="arm_r_link7" class="arm_collision"/>
                    <site name="ee_site" pos="0.107944 0 -0.065588" quat="0.475435 -0.475435 0.523413 0.523413" size="0.005"/>

                    <!-- Right hand (HX5-D20), identical subtree to models/hand_only.xml -->
                    <body name="hx5_r_base" pos="0 0 -0.078" quat="0 0.7071068 0.7071068 0">
                      <inertial pos="-0.00259546 0.00179263 0.0629577" mass="0.301852"
                        diaginertia="0.000542413 0.000389333 0.000210116"/>
                      <geom type="mesh" mesh="hx5_r_base" material="black" class="visual"/>
                      <geom name="palm_collision" type="box" size="0.02421 0.05536 0.06126"
                        pos="-0.00321 -0.00121 0.06126" class="collision"/>

                      <!-- IK target site. The Phase 1/2 validated can placement
                           (models/hand_only.xml) is (0.105, 0.065, 0.16) in WORLD
                           coordinates there, with hx5_r_base at world (0, 0, 0.15). That is
                           NOT the same as a (0.105, 0.065, 0.16) offset in the palm's own
                           LOCAL frame -- this site was defined with that exact bug for most
                           of Phase 3 (copied the world-frame numbers directly), which is
                           the actual root cause of the integrated pick failures, not arm
                           precision (see NOTES.md "Phase 3" for the full story and how the
                           bug was found: finger-to-can relative positions computed here
                           didn't match hand_only.xml's at all, by a large *constant* offset
                           across all three fingers -- the signature of a frame bug, not a
                           joint/control error). Correct local offset, verified by direct
                           computation (palm_R.T @ (can_world_pos - palm_world_pos)):
                           (0.065, 0.01, 0.105). -->
                      <site name="grasp_target" pos="0.065 0.01 0.105" size="0.006" rgba="0 1 0 1"/>

                      <!-- Thumb (4 joints) -->
                      <body name="finger_r_link1" pos="-0.0125 0.03493 0.04475">
                        <inertial pos="0.0238075 0.00131524 0.000460355" mass="0.0408685"
                          diaginertia="2.88193e-06 9.43334e-06 9.65126e-06"/>
                        <joint name="finger_r_joint1" class="thumb_r_cmc"/>
                        <geom type="mesh" mesh="hx5_r_thumb_mcp" material="black" class="visual"/>
                        <geom type="capsule" fromto="-0.000125 0.00225 0  0.037125 0.00225 0" size="0.011375" class="collision"/>
                        <body name="finger_r_link2" pos="0.039 0 0">
                          <inertial pos="-0.000356679 0.0139993 0.000359207" mass="0.0117606"
                            diaginertia="1.30235e-06 1.05564e-06 1.30247e-06"/>
                          <joint name="finger_r_joint2" class="thumb_r_mcp_yaw"/>
                          <geom type="mesh" mesh="hx5_r_thumb_mcp2" material="black" class="visual"/>
                          <geom type="capsule" fromto="0 0.00525 0  0 0.02275 0" size="0.0115" class="collision"/>
                          <body name="finger_r_link3" pos="0 0.028 0">
                            <inertial pos="-0.000101462 0.0113435 4.08056e-06" mass="0.034690"
                              diaginertia="5.03702e-06 2.25807e-06 5.40298e-06"/>
                            <joint name="finger_r_joint3" class="thumb_r_mcp_pitch"/>
                            <geom type="mesh" mesh="hx5_r_thumb_ip" material="black" class="visual"/>
                            <geom type="capsule" fromto="0 0.001 0  0 0.03125 0" size="0.0105" class="collision"/>
                            <body name="finger_r_link4" pos="0 0.0355 0">
                              <inertial pos="6.66050e-05 0.0168245 0.000223985" mass="0.043875"
                                diaginertia="1.11607e-05 2.80794e-06 1.13431e-05"/>
                              <joint name="finger_r_joint4" class="thumb_r_ip"/>
                              <geom type="mesh" mesh="hx5_r_thumb_tip" material="black" class="visual"/>
                              <geom type="capsule" fromto="0 0.0025 0.0015  0 0.0415 0.0015" size="0.012" class="collision"/>
                            </body>
                          </body>
                        </body>
                      </body>

                      <!-- Index finger (4 joints) -->
                      <body name="finger_r_link5" pos="-0.0015 0.03608 0.09575">
                        <inertial pos="0.00519340 -1.81631e-05 0.0211155" mass="0.0388044"
                          diaginertia="3.52499e-06 5.79216e-06 4.71268e-06"/>
                        <joint name="finger_r_joint5" class="finger_mcp"/>
                        <geom type="mesh" mesh="hx5_r_finger_mcp" material="black" class="visual"/>
                        <geom type="capsule" fromto="0.00685 0 0.00858  0.00685 0 0.01818" size="0.014825" class="collision"/>
                        <body name="finger_r_link6" pos="0.0165 0 0.0235">
                          <inertial pos="4.08056e-06 0.000101462 0.0241565" mass="0.034690"
                            diaginertia="5.40298e-06 5.03702e-06 2.25807e-06"/>
                          <joint name="finger_r_joint6" class="finger_pip"/>
                          <geom type="mesh" mesh="hx5_r_finger_pip" material="black" class="visual"/>
                          <geom type="capsule" fromto="0 0 0.004255  0 0 0.034505" size="0.0105" class="collision"/>
                          <body name="finger_r_link7" pos="0 0 0.0355">
                            <inertial pos="4.08056e-06 0.000101462 0.0241565" mass="0.034690"
                              diaginertia="5.40298e-06 5.03702e-06 2.25807e-06"/>
                            <joint name="finger_r_joint7" class="finger_dip"/>
                            <geom type="mesh" mesh="hx5_r_finger_dip" material="black" class="visual"/>
                            <geom type="capsule" fromto="0 0 0.004255  0 0 0.034505" size="0.0105" class="collision"/>
                            <body name="finger_r_link8" pos="0 0 0.0355">
                              <inertial pos="0.000710251 0.000472384 0.0180986" mass="0.013637"
                                diaginertia="2.23243e-06 2.01881e-06 1.07866e-06"/>
                              <joint name="finger_r_joint8" class="finger_tip"/>
                              <geom type="mesh" mesh="hx5_r_finger_tip" material="black" class="visual"/>
                              <geom type="capsule" fromto="0.0015 0 0.006005  0.0015 0 0.025755" size="0.01225" class="collision"/>
                            </body>
                          </body>
                        </body>
                      </body>

                      <!-- Middle finger (4 joints) -->
                      <body name="finger_r_link9" pos="-0.0015 0.00908 0.10353">
                        <inertial pos="0.00519340 -1.81631e-05 0.0211155" mass="0.0388044"
                          diaginertia="3.52499e-06 5.79216e-06 4.71268e-06"/>
                        <joint name="finger_r_joint9" class="finger_mcp"/>
                        <geom type="mesh" mesh="hx5_r_finger_mcp" material="black" class="visual"/>
                        <geom type="capsule" fromto="0.00685 0 0.00858  0.00685 0 0.01818" size="0.014825" class="collision"/>
                        <body name="finger_r_link10" pos="0.0165 0 0.0235">
                          <inertial pos="4.08056e-06 0.000101462 0.0241565" mass="0.034690"
                            diaginertia="5.40298e-06 5.03702e-06 2.25807e-06"/>
                          <joint name="finger_r_joint10" class="finger_pip"/>
                          <geom type="mesh" mesh="hx5_r_finger_pip" material="black" class="visual"/>
                          <geom type="capsule" fromto="0 0 0.004255  0 0 0.034505" size="0.0105" class="collision"/>
                          <body name="finger_r_link11" pos="0 0 0.0355">
                            <inertial pos="4.08056e-06 0.000101462 0.0241565" mass="0.034690"
                              diaginertia="5.40298e-06 5.03702e-06 2.25807e-06"/>
                            <joint name="finger_r_joint11" class="finger_dip"/>
                            <geom type="mesh" mesh="hx5_r_finger_dip" material="black" class="visual"/>
                            <geom type="capsule" fromto="0 0 0.004255  0 0 0.034505" size="0.0105" class="collision"/>
                            <body name="finger_r_link12" pos="0 0 0.0355">
                              <inertial pos="0.000710251 0.000472384 0.0180986" mass="0.013637"
                                diaginertia="2.23243e-06 2.01881e-06 1.07866e-06"/>
                              <joint name="finger_r_joint12" class="finger_tip"/>
                              <geom type="mesh" mesh="hx5_r_finger_tip" material="black" class="visual"/>
                              <geom type="capsule" fromto="0.0015 0 0.006005  0.0015 0 0.025755" size="0.01225" class="collision"/>
                            </body>
                          </body>
                        </body>
                      </body>

                      <!-- Ring finger (4 joints) -- locked at range=0, see NOTES.md Phase 2 -->
                      <body name="finger_r_link13" pos="-0.0015 -0.01792 0.09775">
                        <inertial pos="0.00519340 -1.81631e-05 0.0211155" mass="0.0388044"
                          diaginertia="3.52499e-06 5.79216e-06 4.71268e-06"/>
                        <joint name="finger_r_joint13" class="finger_mcp" range="0 0"/>
                        <geom type="mesh" mesh="hx5_r_finger_mcp" material="black" class="visual"/>
                        <geom type="capsule" fromto="0.00685 0 0.00858  0.00685 0 0.01818" size="0.014825" class="collision"/>
                        <body name="finger_r_link14" pos="0.0165 0 0.0235">
                          <inertial pos="4.08056e-06 0.000101462 0.0241565" mass="0.034690"
                            diaginertia="5.40298e-06 5.03702e-06 2.25807e-06"/>
                          <joint name="finger_r_joint14" class="finger_pip" range="0 0"/>
                          <geom type="mesh" mesh="hx5_r_finger_pip" material="black" class="visual"/>
                          <geom type="capsule" fromto="0 0 0.004255  0 0 0.034505" size="0.0105" class="collision"/>
                          <body name="finger_r_link15" pos="0 0 0.0355">
                            <inertial pos="4.08056e-06 0.000101462 0.0241565" mass="0.034690"
                              diaginertia="5.40298e-06 5.03702e-06 2.25807e-06"/>
                            <joint name="finger_r_joint15" class="finger_dip" range="0 0"/>
                            <geom type="mesh" mesh="hx5_r_finger_dip" material="black" class="visual"/>
                            <geom type="capsule" fromto="0 0 0.004255  0 0 0.034505" size="0.0105" class="collision"/>
                            <body name="finger_r_link16" pos="0 0 0.0355">
                              <inertial pos="0.000710251 0.000472384 0.0180986" mass="0.013637"
                                diaginertia="2.23243e-06 2.01881e-06 1.07866e-06"/>
                              <joint name="finger_r_joint16" class="finger_tip" range="0 0"/>
                              <geom type="mesh" mesh="hx5_r_finger_tip" material="black" class="visual"/>
                              <geom type="capsule" fromto="0.0015 0 0.006005  0.0015 0 0.025755" size="0.01225" class="collision"/>
                            </body>
                          </body>
                        </body>
                      </body>

                      <!-- Pinky finger (4 joints) -- locked at range=0, see NOTES.md Phase 2 -->
                      <body name="finger_r_link17" pos="-0.0015 -0.04492 0.07875">
                        <inertial pos="0.00519340 -1.81631e-05 0.0211155" mass="0.0388044"
                          diaginertia="3.52499e-06 5.79216e-06 4.71268e-06"/>
                        <joint name="finger_r_joint17" class="finger_mcp" range="0 0"/>
                        <geom type="mesh" mesh="hx5_r_finger_mcp" material="black" class="visual"/>
                        <geom type="capsule" fromto="0.00685 0 0.00858  0.00685 0 0.01818" size="0.014825" class="collision"/>
                        <body name="finger_r_link18" pos="0.0165 0 0.0235">
                          <inertial pos="4.08056e-06 0.000101462 0.0241565" mass="0.034690"
                            diaginertia="5.40298e-06 5.03702e-06 2.25807e-06"/>
                          <joint name="finger_r_joint18" class="finger_pip" range="0 0"/>
                          <geom type="mesh" mesh="hx5_r_finger_pip" material="black" class="visual"/>
                          <geom type="capsule" fromto="0 0 0.004255  0 0 0.034505" size="0.0105" class="collision"/>
                          <body name="finger_r_link19" pos="0 0 0.0355">
                            <inertial pos="4.08056e-06 0.000101462 0.0241565" mass="0.034690"
                              diaginertia="5.40298e-06 5.03702e-06 2.25807e-06"/>
                            <joint name="finger_r_joint19" class="finger_dip" range="0 0"/>
                            <geom type="mesh" mesh="hx5_r_finger_dip" material="black" class="visual"/>
                            <geom type="capsule" fromto="0 0 0.004255  0 0 0.034505" size="0.0105" class="collision"/>
                            <body name="finger_r_link20" pos="0 0 0.0355">
                              <inertial pos="0.000710251 0.000472384 0.0180986" mass="0.013637"
                                diaginertia="2.23243e-06 2.01881e-06 1.07866e-06"/>
                              <joint name="finger_r_joint20" class="finger_tip" range="0 0"/>
                              <geom type="mesh" mesh="hx5_r_finger_tip" material="black" class="visual"/>
                              <geom type="capsule" fromto="0.0015 0 0.006005  0.0015 0 0.025755" size="0.01225" class="collision"/>
                            </body>
                          </body>
                        </body>
                      </body>
                    </body>
                  </body>
                </body>
              </body>
            </body>
          </body>
        </body>
      </body>
    </body>
  </worldbody>

  <contact>
    <!-- Hand self-collision excludes, identical rationale to models/hand_only.xml (Phase 2) -->
    <exclude body1="finger_r_link1" body2="finger_r_link2"/>
    <exclude body1="finger_r_link2" body2="finger_r_link3"/>
    <exclude body1="finger_r_link3" body2="finger_r_link4"/>
    <exclude body1="finger_r_link5" body2="finger_r_link6"/>
    <exclude body1="finger_r_link6" body2="finger_r_link7"/>
    <exclude body1="finger_r_link7" body2="finger_r_link8"/>
    <exclude body1="finger_r_link9" body2="finger_r_link10"/>
    <exclude body1="finger_r_link10" body2="finger_r_link11"/>
    <exclude body1="finger_r_link11" body2="finger_r_link12"/>
    <exclude body1="finger_r_link13" body2="finger_r_link14"/>
    <exclude body1="finger_r_link14" body2="finger_r_link15"/>
    <exclude body1="finger_r_link15" body2="finger_r_link16"/>
    <exclude body1="finger_r_link17" body2="finger_r_link18"/>
    <exclude body1="finger_r_link18" body2="finger_r_link19"/>
    <exclude body1="finger_r_link19" body2="finger_r_link20"/>
    <exclude body1="finger_r_link5" body2="finger_r_link9"/>
    <exclude body1="finger_r_link9" body2="finger_r_link13"/>
    <exclude body1="finger_r_link13" body2="finger_r_link17"/>
    <exclude body1="hx5_r_base" body2="finger_r_link1"/>
    <exclude body1="hx5_r_base" body2="finger_r_link2"/>
    <exclude body1="hx5_r_base" body2="finger_r_link5"/>
    <exclude body1="hx5_r_base" body2="finger_r_link6"/>
    <exclude body1="hx5_r_base" body2="finger_r_link9"/>
    <exclude body1="hx5_r_base" body2="finger_r_link10"/>
    <exclude body1="hx5_r_base" body2="finger_r_link13"/>
    <exclude body1="hx5_r_base" body2="finger_r_link14"/>
    <exclude body1="hx5_r_base" body2="finger_r_link17"/>
    <exclude body1="hx5_r_base" body2="finger_r_link18"/>
    <exclude body1="arm_r_link7" body2="hx5_r_base"/>
    <!-- palm_collision is a single solid box standing in for the real (narrower, curved)
         palm mesh (see NOTES.md "Phase 2"). In the validated Phase 1/2 grasp geometry the
         palm sits behind and below the fingertip/grasp point, which puts the box's own bulk
         right at table height when reaching for a can this close to the table surface --
         real box, but not the real palm shape, so it isn't the thing this phase means to
         test. Excluded rather than re-deriving whole-arm collision-free motion planning
         (out of scope -- see NOTES.md "Phase 3"). -->
    <exclude body1="hx5_r_base" body2="world"/>
    <!-- Ring/pinky are locked at range=0 (Phase 2's 3-point grasp fallback) -- fixed,
         inert, out of the active grasp. Their exact resting collision against the
         environment (not the can) isn't what this phase tests; excluded for the same
         reason as the palm above. Still allowed to touch the can, matching Phase 1/2. -->
    <exclude body1="finger_r_link13" body2="world"/>
    <exclude body1="finger_r_link14" body2="world"/>
    <exclude body1="finger_r_link15" body2="world"/>
    <exclude body1="finger_r_link16" body2="world"/>
    <exclude body1="finger_r_link17" body2="world"/>
    <exclude body1="finger_r_link18" body2="world"/>
    <exclude body1="finger_r_link19" body2="world"/>
    <exclude body1="finger_r_link20" body2="world"/>
  </contact>

  <actuator>
    <!-- Arm: pure torque (motor) actuators, driven every step by src/arm_control.py's
         software PD + gravity/Coriolis feedforward (see NOTES.md "Phase 3" for why
         MuJoCo's built-in <position> actuator wasn't accurate enough here: no integral, no
         feedforward, and the per-joint dampratio=1 doesn't critically damp a coupled
         7-link chain). ctrlrange matches the official forcerange values. -->
    <motor name="arm_r_joint1" joint="arm_r_joint1" ctrlrange="-61.4 61.4"/>
    <motor name="arm_r_joint2" joint="arm_r_joint2" ctrlrange="-61.4 61.4"/>
    <motor name="arm_r_joint3" joint="arm_r_joint3" ctrlrange="-31.7 31.7"/>
    <motor name="arm_r_joint4" joint="arm_r_joint4" ctrlrange="-31.7 31.7"/>
    <motor name="arm_r_joint5" joint="arm_r_joint5" ctrlrange="-31.7 31.7"/>
    <motor name="arm_r_joint6" joint="arm_r_joint6" ctrlrange="-31.7 31.7"/>
    <motor name="arm_r_joint7" joint="arm_r_joint7" ctrlrange="-5.1 5.1"/>

    <position class="thumb_r_cmc" name="finger_r_joint1" joint="finger_r_joint1" inheritrange="1"/>
    <position class="thumb_r_mcp_yaw" name="finger_r_joint2" joint="finger_r_joint2" inheritrange="1"/>
    <position class="thumb_r_mcp_pitch" name="finger_r_joint3" joint="finger_r_joint3" inheritrange="1"/>
    <position class="thumb_r_ip" name="finger_r_joint4" joint="finger_r_joint4" inheritrange="1"/>
    <position class="finger_mcp" name="finger_r_joint5" joint="finger_r_joint5" inheritrange="1"/>
    <position class="finger_pip" name="finger_r_joint6" joint="finger_r_joint6" inheritrange="1"/>
    <position class="finger_dip" name="finger_r_joint7" joint="finger_r_joint7" inheritrange="1"/>
    <position class="finger_tip" name="finger_r_joint8" joint="finger_r_joint8" inheritrange="1"/>
    <position class="finger_mcp" name="finger_r_joint9" joint="finger_r_joint9" inheritrange="1"/>
    <position class="finger_pip" name="finger_r_joint10" joint="finger_r_joint10" inheritrange="1"/>
    <position class="finger_dip" name="finger_r_joint11" joint="finger_r_joint11" inheritrange="1"/>
    <position class="finger_tip" name="finger_r_joint12" joint="finger_r_joint12" inheritrange="1"/>
  </actuator>

  <!-- "home": arm at a ready pose 10cm back / 20cm above the can (HOME_Q in
       tests/test_phase_3.py, found via IK), well clear of the table. Recomputed after
       fixing the grasp_target site definition bug -- see NOTES.md "Phase 3": the site's
       local offset was copy-pasted from hand_only.xml's can *world* position without
       transforming into the palm's local frame, so every arm pose computed against it
       before the fix targeted the wrong physical point on the hand. Hand in its Phase 2
       pregrasp shape. -->
  <keyframe>
    <key name="home"
      qpos="0.5 0.0 0.705  1 0 0 0
            -0.225 -0.394 0.682 -2.613 -0.704 0.843 -1.218
            0.131 -1.309 0 0
            0 0.4014 0.3142 0.3142
            0 0.4014 0.3142 0.3142
            0 0 0 0
            0 0 0 0"
      ctrl="0 0 0 0 0 0 0
            0.131 -1.309 0 0
            0 0.4014 0.3142 0.3142
            0 0.4014 0.3142 0.3142"/>
  </keyframe>
</mujoco>
