<mujoco model="full_scene">
  <compiler angle="radian" meshdir="../assets/robotis_ffw/assets" autolimits="true"/>

  <option timestep="0.001" integrator="implicitfast" cone="elliptic" impratio="10"/>

  <visual>
    <headlight diffuse="0.6 0.6 0.6" ambient="0.3 0.3 0.3" specular="0 0 0"/>
    <rgba haze="0.15 0.25 0.35 1"/>
    <global azimuth="120" elevation="-20" offwidth="1280" offheight="960"/>
  </visual>

  <asset>
    <texture type="skybox" builtin="gradient" rgb1="0.3 0.5 0.7" rgb2="0 0 0" width="512" height="3072"/>
    <texture type="2d" name="groundplane" builtin="checker" mark="edge" rgb1="0.2 0.3 0.4" rgb2="0.1 0.2 0.3"
      markrgb="0.8 0.8 0.8" width="300" height="300"/>
    <material name="groundplane" texture="groundplane" texuniform="true" texrepeat="5 5" reflectance="0.2"/>
    <material name="black" rgba="0.2 0.2 0.2 1"/>
    <material name="white" rgba="1 1 1 1"/>
    <material name="grey" rgba="0.7 0.7 0.7 1"/>
    <material name="table_mat" rgba="0.55 0.4 0.3 1"/>

    <!-- Can visual mesh + label texture (Session 8 후속 9, rewritten 후속 10 to use the
         actual detailed STL instead of a bare substitute cylinder -- see below). Source
         mesh: the sibling ffw-sh5-teleoperation repo's assets/soda_can_stl/soda_can.stl,
         copied in (assets/soda_can/), not referenced by absolute path, matching how
         assets/robotis_ffw was vendored in Phase 0. Label texture: the same repo's
         soda_can_color2.png (4096x4096 UV atlas for the mesh's own -- MuJoCo-unreadable,
         STL never carries UV -- layout); cropped out just the label island (the full
         circumferential wrap, already doubled around 360 deg in the source art) and
         downscaled to assets/soda_can/soda_can_label.png (1024px).

         Getting the label to actually wrap around the can took two attempts. First tried a
         plain `type="cylinder"` primitive geom (not the real mesh at all), expecting
         MuJoCo to auto-generate circumferential texture coordinates -- confirmed
         empirically (dumped MuJoCo's own loaded texture pixel data to rule out a
         load/decode bug first) that a primitive cylinder's auto-UV does not produce a
         usable single wrap for a detailed 2D image; every viewing angle showed the same
         compressed/aliased slice regardless of texture resolution or geom scale.

         Second attempt (current): re-derive real UV coordinates for the actual soda_can.stl
         geometry instead of substituting a bare cylinder, so the rendered can keeps the
         mesh's rim/pull-tab/domed-top/concave-base detail. `tests/generate_can_label_mesh.py`
         profiles the STL's own vertex radius vs. height (it's a near-perfect constant-radius
         cylinder from about 5% to 92% of its height, with the rest of its ~15k vertices
         concentrated in the complex top/bottom caps -- a face-normal heuristic was tried
         first and rejected, see NOTES.md "Phase 5 후속 10", because the tab/rim detail is
         locally steep enough to fool it), splits the mesh's faces into that side band vs.
         the two cap regions by height, and computes real UV for the side faces (u = angle
         around the can's own axis, unwrapped per-face to avoid a seam artifact since this
         is an irregular triangulation, not a hand-built regular grid; v = height fraction).
         Produces two OBJs (OBJ, unlike STL, supports `vt` lines) sharing the STL's original
         vertex positions exactly: can_side_detail.obj (label texture) and
         can_cap_detail.obj (plain aluminum color, no meaningful UV needed). Verified with a
         render sweep including a close-up on the pull-tab -- wraps cleanly, seamless
         join between the two pieces since both come from the same source mesh. -->
    <texture type="2d" name="can_label" file="../assets/soda_can/soda_can_label.png"/>
    <material name="can_mat" texture="can_label" specular="0.3" shininess="0.4"/>
    <material name="can_cap_mat" rgba="0.82 0.82 0.85 1" specular="0.6" shininess="0.6"/>
    <mesh name="can_side_detail" file="../../soda_can/can_side_detail.obj" scale="1.1 1.1 0.7333"/>
    <mesh name="can_cap_detail" file="../../soda_can/can_cap_detail.obj" scale="1.1 1.1 0.7333"/>


    <mesh name="base_mobile_assy" file="ffw_s/base_mobile_assy.stl" scale="0.001 0.001 0.001"/>
    <mesh name="left_wheel" file="ffw_s/left_wheel_drive_link.stl" scale="0.001 0.001 0.001"/>
    <mesh name="right_wheel" file="ffw_s/right_wheel_drive_link.stl" scale="0.001 0.001 0.001"/>
    <mesh name="rear_wheel" file="ffw_s/rear_wheel_drive_link.stl" scale="0.001 0.001 0.001"/>
    <mesh name="lift_link" file="ffw_s/lift_link.stl" scale="0.001 0.001 0.001"/>
    <mesh name="body_arm_assy" file="ffw_s/body_arm_assy.stl" scale="0.001 0.001 0.001"/>
    <mesh name="head_link1" file="ffw_s/head_link1.stl" scale="0.001 0.001 0.001"/>
    <mesh name="head_link2" file="ffw_s/head_link2.stl" scale="0.001 0.001 0.001"/>
    <mesh name="arm_l_link1" file="ffw_s/arm_l_link1.stl" scale="0.001 0.001 0.001"/>
    <mesh name="arm_l_link2" file="ffw_s/arm_l_link2.stl" scale="0.001 0.001 0.001"/>
    <mesh name="arm_l_link3" file="ffw_s/arm_l_link3.stl" scale="0.001 0.001 0.001"/>
    <mesh name="arm_l_link4" file="ffw_s/arm_l_link4.stl" scale="0.001 0.001 0.001"/>
    <mesh name="arm_l_link5" file="ffw_s/arm_l_link5.stl" scale="0.001 0.001 0.001"/>
    <mesh name="arm_l_link6" file="ffw_s/arm_l_link6.stl" scale="0.001 0.001 0.001"/>
    <mesh name="arm_l_link7" file="ffw_s/arm_l_link7.stl" scale="0.001 0.001 0.001"/>
    <mesh name="arm_r_link1" file="ffw_s/arm_r_link1.stl" scale="0.001 0.001 0.001"/>
    <mesh name="arm_r_link2" file="ffw_s/arm_r_link2.stl" scale="0.001 0.001 0.001"/>
    <mesh name="arm_r_link3" file="ffw_s/arm_r_link3.stl" scale="0.001 0.001 0.001"/>
    <mesh name="arm_r_link4" file="ffw_s/arm_r_link4.stl" scale="0.001 0.001 0.001"/>
    <mesh name="arm_r_link5" file="ffw_s/arm_r_link5.stl" scale="0.001 0.001 0.001"/>
    <mesh name="arm_r_link6" file="ffw_s/arm_r_link6.stl" scale="0.001 0.001 0.001"/>
    <mesh name="arm_r_link7" file="ffw_s/arm_r_link7.stl" scale="0.001 0.001 0.001"/>
    <mesh name="hx5_l_base" file="hx5_d20/hx5_d20_left/hx5_d20_base_unit.stl" scale="0.001 0.001 0.001"/>
    <mesh name="hx5_l_thumb_mcp" file="hx5_d20/hx5_d20_left/hx5_d20_thumb_mcp.stl" scale="0.001 0.001 0.001"/>
    <mesh name="hx5_l_thumb_mcp2" file="hx5_d20/hx5_d20_left/hx5_d20_thumb_mcp2.stl" scale="0.001 0.001 0.001"/>
    <mesh name="hx5_l_thumb_ip" file="hx5_d20/hx5_d20_left/hx5_d20_thumb_ip.stl" scale="0.001 0.001 0.001"/>
    <mesh name="hx5_l_thumb_tip" file="hx5_d20/hx5_d20_left/hx5_d20_thumb_tip.stl" scale="0.001 0.001 0.001"/>
    <mesh name="hx5_l_finger_mcp" file="hx5_d20/hx5_d20_left/hx5_d20_finger_mcp.stl" scale="0.001 0.001 0.001"/>
    <mesh name="hx5_l_finger_pip" file="hx5_d20/hx5_d20_left/hx5_d20_finger_pip.stl" scale="0.001 0.001 0.001"/>
    <mesh name="hx5_l_finger_dip" file="hx5_d20/hx5_d20_left/hx5_d20_finger_dip.stl" scale="0.001 0.001 0.001"/>
    <mesh name="hx5_l_finger_tip" file="hx5_d20/hx5_d20_left/hx5_d20_finger_tip.stl" scale="0.001 0.001 0.001"/>
    <mesh name="hx5_r_base" file="hx5_d20/hx5_d20_right/hx5_d20_base_unit.stl" scale="0.001 0.001 0.001"/>
    <mesh name="hx5_r_thumb_mcp" file="hx5_d20/hx5_d20_right/hx5_d20_thumb_mcp.stl" scale="0.001 0.001 0.001"/>
    <mesh name="hx5_r_thumb_mcp2" file="hx5_d20/hx5_d20_right/hx5_d20_thumb_mcp2.stl" scale="0.001 0.001 0.001"/>
    <mesh name="hx5_r_thumb_ip" file="hx5_d20/hx5_d20_right/hx5_d20_thumb_ip.stl" scale="0.001 0.001 0.001"/>
    <mesh name="hx5_r_thumb_tip" file="hx5_d20/hx5_d20_right/hx5_d20_thumb_tip.stl" scale="0.001 0.001 0.001"/>
    <mesh name="hx5_r_finger_mcp" file="hx5_d20/hx5_d20_right/hx5_d20_finger_mcp.stl" scale="0.001 0.001 0.001"/>
    <mesh name="hx5_r_finger_pip" file="hx5_d20/hx5_d20_right/hx5_d20_finger_pip.stl" scale="0.001 0.001 0.001"/>
    <mesh name="hx5_r_finger_dip" file="hx5_d20/hx5_d20_right/hx5_d20_finger_dip.stl" scale="0.001 0.001 0.001"/>
    <mesh name="hx5_r_finger_tip" file="hx5_d20/hx5_d20_right/hx5_d20_finger_tip.stl" scale="0.001 0.001 0.001"/>
  </asset>

<default>
    <!-- Wheel steering -->
    <default class="wheel_steer">
      <joint frictionloss="0.1" armature="0.5" damping="200.0"/>
      <position kp="5000" forcerange="-2000 2000"/>
      <default class="left_wheel_steer">
        <joint axis="0 0 1" range="-1.58 1.58"/>
      </default>
      <default class="right_wheel_steer">
        <joint axis="0 0 1" range="-1.58 1.58"/>
      </default>
      <default class="rear_wheel_steer">
        <joint axis="0 0 1" range="-1.58 1.58"/>
      </default>
    </default>
    <!-- Wheel drive. kv raised from the vendored ffw_sh5.xml's 1 (Session 8 후속): a
         velocity actuator only develops torque proportional to (ctrl - qvel), and at kv=1
         the wheel's own rotational inertia is so much smaller than the ~100kg base+arms it
         must accelerate via ground friction that it settles near its own target speed while
         delivering nowhere near enough sustained torque to also move the base -- measured
         directly, base crawled <2mm in 4s of "full speed" forward commands. kv=30 reaches
         ~90% of the commanded cruise speed with no added instability (max|qacc| unchanged
         from baseline).
         Raised again 30->150 (Session 8 후속 8, alongside the wheel-floor solref retune to
         "0.15 1" above) once the contact-stiffness bug was fixed and in-place rotation was
         still far under its commanded rate: swept kv up to 1500 against both in-place
         rotation rate and straight-line speed/slip -- rotation improves steadily through
         kv=200 then gets noisy/non-monotonic beyond it (a sign something else, likely the
         rear wheel's near-boundary steer angle, starts dominating rather than kv itself),
         while straight-line speed/slip stays flat-to-improving the whole way and idle drift
         never changes (as expected, kv only matters when there's a drive command). kv=150
         combined with solref="0.15 1" gave the best rotation improvement (~23% of commanded
         vs ~0.5% before any of this) with the lowest peak transient among the combinations
         swept, and improved straight-line speed as a side effect (0.46->0.49 m/s). -->
    <default class="wheel_drive">
      <joint type="hinge" axis="0 1 0" damping="2" frictionloss="0.2"/>
      <velocity kv="150" ctrlrange="-50 50" ctrllimited="true"/>
    </default>
    <!-- Slider: lift_joint. kp raised from the official 10000 (Session 8, Phase 5 후속):
         this is a plain <position> actuator with no gravity feedforward (same class of
         issue Phase 3 hit with the arms, see src/arm_control.py), so it has a real
         proportional-only static droop under load -- measured directly: qfrc_bias on this
         DOF is ~323N regardless of arm pose (total system weight along the lift axis is
         pose-invariant, confirmed empirically), so droop ~= 323/kp. This was invisible at
         kp=10000 with the old "arms already reaching for the table" pose (converged to
         <0.3mm quickly for reasons not fully explained -- possibly a lucky low-vibration
         settling path) but became a ~30mm+ slowly-growing sag once the home pose changed to
         match ffw-sh5-mujoco's rest pose (arms hanging, elbow -90 deg) -- same total load,
         different transient dynamics exposed the same latent per-actuator weakness a much
         higher kp (like arm_control.py's feedforward) fixes directly. kp=500000 keeps droop
         under ~0.7mm with no added instability (max|qacc| unchanged). -->
    <default class="slider">
      <joint type="slide" frictionloss="100.0" armature="10.0" damping="5000.0"/>
      <position kp="500000" forcerange="-100000 100000"/>
      <default class="lift_joint">
        <joint axis="0 0 1" range="-0.5 0.0"/>
      </default>
    </default>
    <!-- Mobile base: planar virtual joint (Phase 5) -- 3 real DOF (slide x, slide y, hinge
         yaw) on base_link replacing the freejoint the official model would otherwise need,
         driven by velocity actuators (see src/base_teleop.py). This is the MuJoCo-native
         equivalent of the sibling ffw-sh5-teleoperation repo's kinematic transform+sweep-test
         base (see ffw-sh5-mobile-and-box-plan.md S3.1) -- collision sliding against
         obstacles (e.g. the table, T9) comes free from the constraint solver instead of a
         hand-rolled sweep test, and it does not touch qpos directly (ctrl only). -->
    <!-- frictionloss (Coulomb/static friction, N or N*m) matters here beyond the usual
         "avoid numerical stiffness" role: a pure <velocity> actuator has zero position
         stiffness, so with damping alone a small constant disturbance (e.g. reaction force
         from the arms settling into a held pose) drives the base to a nonzero *steady-state*
         velocity instead of zero -- measured directly: a 5s arm-hold-only test (no drive
         keys) drifted the base 63-67mm/3.75 degrees with damping alone. frictionloss adds
         real static friction that fully cancels disturbances below its threshold (sized with
         margin above the ~2-16N/6N*m measured at that steady state) while barely denting the
         ~500N/200N*m drive authority used for actual WASD driving. -->
    <default class="base_planar">
      <joint type="slide" damping="50" frictionloss="30" armature="0.05"/>
      <velocity kv="800" ctrlrange="-1 1" ctrllimited="true" forcerange="-500 500"/>
    </default>
    <default class="base_yaw">
      <joint type="hinge" axis="0 0 1" damping="20" frictionloss="10" armature="0.05"/>
      <velocity kv="200" ctrlrange="-3 3" ctrllimited="true" forcerange="-200 200"/>
    </default>
    <!-- Head motor -->
    <default class="head">
      <joint frictionloss="0.1" armature="0.1" damping="5.0"/>
      <position kp="200" dampratio="1" forcerange="-10 10"/>
      <default class="head_joint1">
        <joint axis="0 1 0" range="-0.2317 0.6951"/>
      </default>
      <default class="head_joint2">
        <joint axis="0 0 1" range="-0.35 0.35"/>
      </default>
    </default>
    <!-- DY-80 motor: arm joint 1, 2 -->
    <default class="DY_80">
      <joint frictionloss="0.1" armature="0.5" damping="30.0"/>
      <position kp="600" dampratio="1" forcerange="-61.4 61.4"/>
      <default class="arm_l_joint1">
        <joint axis="0 1 0" range="-3.14 3.14"/>
      </default>
      <default class="arm_l_joint2">
        <joint axis="1 0 0" range="0 3.14"/>
      </default>
      <default class="arm_r_joint1">
        <joint axis="0 1 0" range="-3.14 3.14"/>
      </default>
      <default class="arm_r_joint2">
        <joint axis="1 0 0" range="-3.14 0"/>
      </default>
    </default>
    <!-- DY-70 motor: arm joint 3, 4, 5, 6 -->
    <default class="DY_70">
      <joint frictionloss="0.1" armature="0.5" damping="20.0"/>
      <position kp="600" dampratio="1" forcerange="-31.7 31.7"/>
      <default class="arm_l_joint3">
        <joint axis="0 0 1" range="-3.14 3.14"/>
      </default>
      <default class="arm_l_joint4">
        <joint axis="0 1 0" range="-2.9361 1.0786"/>
      </default>
      <default class="arm_l_joint5">
        <joint axis="0 0 1" range="-3.14 3.14"/>
      </default>
      <default class="arm_l_joint6">
        <joint axis="0 1 0" range="-1.57 1.57"/>
      </default>
      <default class="arm_r_joint3">
        <joint axis="0 0 1" range="-3.14 3.14"/>
      </default>
      <default class="arm_r_joint4">
        <joint axis="0 1 0" range="-2.9361 1.0786"/>
      </default>
      <default class="arm_r_joint5">
        <joint axis="0 0 1" range="-3.14 3.14"/>
      </default>
      <default class="arm_r_joint6">
        <joint axis="0 1 0" range="-1.57 1.57"/>
      </default>
    </default>
    <!-- DP-42 motor: arm joint 7 -->
    <default class="DP_42">
      <joint frictionloss="0.1" armature="0.1" damping="3.0"/>
      <position kp="200" dampratio="1" forcerange="-5.1 5.1"/>
      <default class="arm_l_joint7">
        <joint axis="1 0 0" range="-1.8201 1.5804"/>
      </default>
      <default class="arm_r_joint7">
        <joint axis="1 0 0" range="-1.5804 1.8201"/>
      </default>
    </default>
    <!-- HX5-D20 5-finger hand -->
    <default class="finger">
      <joint frictionloss="0.05" armature="0.05" damping="1.0"/>
      <position kp="20" dampratio="1" forcerange="-2.0 2.0"/>
      <!-- Left Thumb joints -->
      <default class="thumb_l_cmc">
        <joint axis="1 0 0" range="-1.5708 1.5708"/>
      </default>
      <default class="thumb_l_mcp_yaw">
        <joint axis="0 0 1" range="0 3.1416"/>
      </default>
      <default class="thumb_l_mcp_pitch">
        <joint axis="1 0 0" range="-1.5708 0"/>
      </default>
      <default class="thumb_l_ip">
        <joint axis="1 0 0" range="-1.5708 0"/>
      </default>
      <!-- Right Thumb joints -->
      <default class="thumb_r_cmc">
        <joint axis="1 0 0" range="-1.5708 1.5708"/>
      </default>
      <default class="thumb_r_mcp_yaw">
        <joint axis="0 0 1" range="-3.1416 0"/>
      </default>
      <default class="thumb_r_mcp_pitch">
        <joint axis="1 0 0" range="0 1.5708"/>
      </default>
      <default class="thumb_r_ip">
        <joint axis="1 0 0" range="0 1.5708"/>
      </default>
      <!-- Finger MCP Roll (spread) -->
      <default class="finger_mcp">
        <joint axis="1 0 0" range="-0.6109 0.6109"/>
      </default>
      <!-- Finger MCP Pitch (flex) -->
      <default class="finger_pip">
        <joint axis="0 1 0" range="0 2.0071"/>
      </default>
      <!-- Finger PIP -->
      <default class="finger_dip">
        <joint axis="0 1 0" range="0 1.5708"/>
      </default>
      <!-- Finger DIP -->
      <default class="finger_tip">
        <joint axis="0 1 0" range="0 1.5708"/>
      </default>
    </default>
    <!-- Visual / Collision -->
    <default class="visual">
      <geom type="mesh" contype="0" conaffinity="0" density="0" group="2"/>
    </default>
    <default class="collision">
      <geom group="3" type="mesh"/>
    </default>
    <!-- Hand capsule collision: shadow_hand recipe (Phase 1/2/3), distinct from the plain
         mesh "collision" class above so this doesn't change contact behavior for the rest
         of the body (arms, head, torso). -->
    <default class="hand_collision">
      <geom group="3" contype="1" conaffinity="1" condim="3" solimp="0.5 0.99 0.0001" solref="0.005 1"/>
    </default>
  </default>

  <worldbody>
    <light pos="0 0 2.2" dir="0 0 -1" directional="true"/>
    <!-- z=0.148 (Session 8 후속, wheel-friction locomotion): the wheel collision cylinders'
         own resting height (radius 0.09, center world z=0.2365 at the authored base_link/
         wheel pose, measured directly via mj_forward) is exactly 0.1465, but placing the
         floor at EXACTLY that height left it sitting at a numerically unstable zero-gap
         boundary -- measured directly: with pos=0.1465 only the rear wheel kept a contact
         (front-left/front-right silently dropped out of `data.contact`, all three wheels'
         xpos identical to float precision) and the base could not move at all (>99% wheel
         slip, since two of three contact patches simply weren't there). A deliberate ~1.5mm
         overlap makes contact detection robust for all three wheels; verified directly
         (wheel rolling speed now matches actual base velocity, no slip). Arm/table/can
         height calibration (Phase 4) is untouched -- this only redefines where "the ground"
         is, not where base_link/the arm sit. -->
    <geom name="floor" size="0 0 0.05" type="plane" pos="0 0 0.148" material="groundplane"/>

    <body name="base_link" pos="0 0 0.15">
      <joint name="base_x" class="base_planar" axis="1 0 0"/>
      <joint name="base_y" class="base_planar" axis="0 1 0"/>
      <joint name="base_yaw" class="base_yaw"/>
      <inertial pos="-0.0457 0.0066 0.1943" mass="35.99" diaginertia="0.65 0.65 0.96"/>

      <!-- base_mobile_assy visual -->
      <geom type="mesh" mesh="base_mobile_assy" material="black" class="visual"/>
      <!-- base_mobile_assy collision -->
      <geom type="box" size="0.2 0.2 0.12" pos="0 0 0.24" rgba="0 0 0 0"/>

      <!-- Left front wheel (steering + driving) -- real joints restored (Session 8 후속,
           see src/base_teleop.py) from the vendored ffw_sh5.xml's own wheel_steer/wheel_drive
           default classes (already present above, just unused since Phase 4 removed these
           joints for simplicity). Ground contact is what actually propels the base now --
           the base_x/base_y/base_yaw joints on base_link stay (keeps the base from tipping/
           rolling, an intentional simplification vs. the vendored model's full 6dof
           floating_base freejoint) but are no longer directly actuated; wheel-ground
           friction, transmitted through these steer/drive joints, is what pushes base_link
           along them now. -->
      <body name="left_wheel_steer" pos="0.1371 0.2554 0.27555">
        <inertial pos="0 0 0" mass="0.5" diaginertia="0.001 0.001 0.001"/>
        <joint name="left_wheel_steer_joint" class="left_wheel_steer"/>
        <body name="left_wheel_drive" pos="0 0 -0.18905">
          <inertial pos="0 -0.0015 0" mass="3.80" diaginertia="0.00719 0.01156 0.00719"/>
          <joint name="left_wheel_drive_joint" class="wheel_drive"/>
          <geom type="mesh" mesh="left_wheel" friction="5.0 1.0 0.3" class="visual"/>
          <geom name="left_wheel_collision" type="cylinder" size="0.09 0.035" quat="0.707107 -0.707107 0 0" friction="5.0 1.0 0.3" group="3"/>
        </body>
      </body>

      <!-- Right front wheel (steering + driving) -->
      <body name="right_wheel_steer" pos="0.1371 -0.2554 0.27555">
        <inertial pos="0 0 0" mass="0.5" diaginertia="0.001 0.001 0.001"/>
        <joint name="right_wheel_steer_joint" class="right_wheel_steer"/>
        <body name="right_wheel_drive" pos="0 0 -0.18905">
          <inertial pos="0 0.0015 0" mass="3.80" diaginertia="0.00719 0.01156 0.00719"/>
          <joint name="right_wheel_drive_joint" class="wheel_drive"/>
          <geom type="mesh" mesh="right_wheel" friction="5.0 1.0 0.3" class="visual"/>
          <geom name="right_wheel_collision" type="cylinder" size="0.09 0.035" quat="0.707107 -0.707107 0 0" friction="5.0 1.0 0.3" group="3"/>
        </body>
      </body>

      <!-- Rear wheel (steering + driving) -->
      <body name="rear_wheel_steer" pos="-0.2899 0 0.27555">
        <inertial pos="0 0 0" mass="0.5" diaginertia="0.001 0.001 0.001"/>
        <joint name="rear_wheel_steer_joint" class="rear_wheel_steer"/>
        <body name="rear_wheel_drive" pos="0 0 -0.18905">
          <inertial pos="0 -0.0015 0" mass="3.80" diaginertia="0.00719 0.01156 0.00719"/>
          <joint name="rear_wheel_drive_joint" class="wheel_drive"/>
          <geom type="mesh" mesh="rear_wheel" friction="5.0 1.0 0.3" class="visual"/>
          <geom name="rear_wheel_collision" type="cylinder" size="0.09 0.035" quat="0.707107 -0.707107 0 0" friction="5.0 1.0 0.3" group="3"/>
        </body>
      </body>

      <!-- Lift link -->
      <body name="lift_link" pos="0 0 0">
        <inertial pos="-0.12869878 -0.00001604 0.89456017" mass="17.9" diaginertia="1.5 1.5 0.05"/>
        <geom type="mesh" mesh="lift_link" material="grey" class="visual"/>
        <geom type="mesh" mesh="lift_link" class="collision"/>

        <!-- arm_base_link -->
        <body name="arm_base_link" pos="0.0055 0 1.4316">
          <inertial pos="-0.0460732 -2.28101e-05 -0.0270208" quat="0.295276 0.295528 -0.642514 0.642379" mass="8.72176" diaginertia="0.106112 0.0836519 0.0576143"/>
          <joint name="lift_joint" class="lift_joint"/>
          <geom type="mesh" mesh="body_arm_assy" material="white" class="visual"/>
          <geom type="mesh" mesh="body_arm_assy" class="collision"/>

          <!-- Head -->
          <body name="head_link1" pos="0.0494878 0 0.102123">
            <joint name="head_joint1" class="head_joint1"/>
            <geom type="mesh" mesh="head_link1" material="black" class="visual"/>
            <geom type="mesh" mesh="head_link1" class="collision"/>

            <body name="head_link2" pos="0.0365694 0 0.0563797">
              <joint name="head_joint2" class="head_joint2"/>
              <geom type="mesh" mesh="head_link2" material="white" class="visual"/>
              <geom type="mesh" mesh="head_link2" class="collision"/>
            </body>
          </body>

          <!-- Left arm -->
          <body name="arm_l_link1" pos="0 0.1045 0">
            <inertial pos="0.0162539 0.115097 0.000116015" quat="-0.229615 0.677745 0.212586 0.665391" mass="1.93395" diaginertia="0.00305502 0.0027509 0.00221577"/>
            <joint name="arm_l_joint1" class="arm_l_joint1"/>
            <geom type="mesh" mesh="arm_l_link1" material="black" class="visual"/>
            <geom type="mesh" mesh="arm_l_link1" class="collision"/>

            <body name="arm_l_link2" pos="0 0.123 0">
              <inertial pos="0.00909681 -0.000105504 -0.144033" quat="0.692968 0.108459 0.106285 0.704795" mass="2.12414" diaginertia="0.0108537 0.0106882 0.00241736"/>
              <joint name="arm_l_joint2" class="arm_l_joint2"/>
              <geom type="mesh" mesh="arm_l_link2" material="black" class="visual"/>
              <geom type="mesh" mesh="arm_l_link2" class="collision"/>

              <body name="arm_l_link3" pos="0 0 -0.165">
                <inertial pos="2.51092e-05 0.0179472 -0.108757" quat="0.894344 0.447371 -0.000598238 0.00281074" mass="1.40774" diaginertia="0.00193356 0.00173187 0.00129028"/>
                <joint name="arm_l_joint3" class="arm_l_joint3"/>
                <geom type="mesh" mesh="arm_l_link3" material="black" class="visual"/>
                <geom type="mesh" mesh="arm_l_link3" class="collision"/>

                <body name="arm_l_link4" pos="0.041004 0 -0.135">
                  <inertial pos="-4.39703e-05 0.00978704 -0.137888" quat="0.984403 -0.175803 -0.00125587 -0.00649472" mass="1.51314" diaginertia="0.00636289 0.00628017 0.00133396"/>
                  <joint name="arm_l_joint4" class="arm_l_joint4"/>
                  <geom type="mesh" mesh="arm_l_link4" material="black" class="visual"/>
                  <geom type="mesh" mesh="arm_l_link4" class="collision"/>

                  <body name="arm_l_link5" pos="-0.041004 0 -0.1489">
                    <inertial pos="-4.95306e-05 0.0187957 -0.0983639" quat="0.838675 0.544584 0.00138926 -0.00713051" mass="1.34419" diaginertia="0.00169917 0.00156903 0.00116769"/>
                    <joint name="arm_l_joint5" class="arm_l_joint5"/>
                    <geom type="mesh" mesh="arm_l_link5" material="black" class="visual"/>
                    <geom type="mesh" mesh="arm_l_link5" class="collision"/>

                    <body name="arm_l_link6" pos="0 0 -0.1041">
                      <inertial pos="0.00038449 0.0194298 -0.0639456" quat="0.658925 -0.254422 0.24959 0.662414" mass="0.636234" diaginertia="0.00155561 0.00138897 0.00049676"/>
                      <joint name="arm_l_joint6" class="arm_l_joint6"/>
                      <geom type="mesh" mesh="arm_l_link6" material="black" class="visual"/>
                      <geom type="mesh" mesh="arm_l_link6" class="collision"/>

                      <body name="arm_l_link7" pos="0 0 -0.0885">
                        <inertial pos="-0.00237181 0.00249345 -0.0980007" quat="0.707876 -0.0176581 -0.0477307 0.704501" mass="0.384359" diaginertia="0.00141022 0.00125626 0.000287964"/>
                        <joint name="arm_l_joint7" class="arm_l_joint7"/>
                        <geom type="mesh" mesh="arm_l_link7" material="black" class="visual"/>
                        <geom type="mesh" mesh="arm_l_link7" class="collision"/>
                        <geom size="0.0115 0.021 0.021" pos="0.107944 0 -0.065588" quat="0.475435 -0.475435 0.523413 0.523413" type="box"/>

                        <!-- Left hand (HX5-D20) -->
                        <body name="hx5_l_base" pos="0 0 -0.078" quat="0 -0.7071068 0.7071068 0">
                          <inertial pos="-0.00262263 -0.00168363 0.0622837" mass="0.301852" diaginertia="0.000528544 0.000382320 0.000201250"/>
                          <geom type="mesh" mesh="hx5_l_base" material="black" class="visual"/>
                          <geom name="palm_l_collision" type="box" size="0.02421 0.05536 0.06126" pos="-0.00321 0.00121 0.06126" class="hand_collision"/>
                          <site name="grasp_target_l" pos="0.065 -0.01 0.105" size="0.006" rgba="0 1 0 1"/>

                          <!-- Thumb (4 joints) -->
                          <body name="finger_l_link1" pos="-0.0125 -0.03493 0.04475">
                            <inertial pos="0.0238075 -0.00138644 -1.72456e-05" mass="0.0408685" diaginertia="2.88272e-06 9.39968e-06 9.68571e-06"/>
                            <joint name="finger_l_joint1" class="thumb_l_cmc"/>
                            <geom type="mesh" mesh="hx5_l_thumb_mcp" material="black" class="visual"/>
                            <geom type="capsule" fromto="-0.000125 -0.00225 0  0.037125 -0.00225 0" size="0.011375" class="hand_collision"/>
                            <body name="finger_l_link2" pos="0.039 0 0">
                              <inertial pos="0.000356679 -0.0139993 0.000359207" mass="0.0117606" diaginertia="1.30235e-06 1.05564e-06 1.30247e-06"/>
                              <joint name="finger_l_joint2" class="thumb_l_mcp_yaw"/>
                              <geom type="mesh" mesh="hx5_l_thumb_mcp2" material="black" class="visual"/>
                              <geom type="capsule" fromto="0 -0.00525 0  0 -0.02275 0" size="0.0115" class="hand_collision"/>
                              <body name="finger_l_link3" pos="0 -0.028 0">
                                <inertial pos="0.000101462 -0.0113435 4.08056e-06" mass="0.034690" diaginertia="5.03702e-06 2.25807e-06 5.40298e-06"/>
                                <joint name="finger_l_joint3" class="thumb_l_mcp_pitch"/>
                                <geom type="mesh" mesh="hx5_l_thumb_ip" material="black" class="visual"/>
                                <geom type="capsule" fromto="0 -0.001 0  0 -0.03125 0" size="0.0105" class="hand_collision"/>
                                <body name="finger_l_link4" pos="0 -0.0355 0">
                                  <inertial pos="-1.79389e-05 -0.0168391 0.000236024" mass="0.043781" diaginertia="1.12255e-05 2.79566e-06 1.1393e-05"/>
                                  <joint name="finger_l_joint4" class="thumb_l_ip"/>
                                  <geom type="mesh" mesh="hx5_l_thumb_tip" material="black" class="visual"/>
                                  <geom type="capsule" fromto="0 -0.0025 0.0015  0 -0.0415 0.0015" size="0.012" class="hand_collision"/>
                                </body>
                              </body>
                            </body>
                          </body>

                          <!-- Index finger (4 joints) -->
                          <body name="finger_l_link5" pos="-0.0015 -0.03608 0.09575">
                            <inertial pos="0.00519340 -1.81631e-05 0.0211155" mass="0.0388044" diaginertia="3.52499e-06 5.79216e-06 4.71268e-06"/>
                            <joint name="finger_l_joint5" class="finger_mcp"/>
                            <geom type="mesh" mesh="hx5_l_finger_mcp" material="black" class="visual"/>
                            <geom type="capsule" fromto="0.00685 0 0.00858  0.00685 0 0.01818" size="0.014825" class="hand_collision"/>
                            <body name="finger_l_link6" pos="0.0165 0 0.0235">
                              <inertial pos="4.08056e-06 0.000101462 0.0241565" mass="0.034690" diaginertia="5.40298e-06 5.03702e-06 2.25807e-06"/>
                              <joint name="finger_l_joint6" class="finger_pip"/>
                              <geom type="mesh" mesh="hx5_l_finger_pip" material="black" class="visual"/>
                              <geom type="capsule" fromto="0 0 0.004255  0 0 0.034505" size="0.0105" class="hand_collision"/>
                              <body name="finger_l_link7" pos="0 0 0.0355">
                                <inertial pos="4.08056e-06 0.000101462 0.0241565" mass="0.034690" diaginertia="5.40298e-06 5.03702e-06 2.25807e-06"/>
                                <joint name="finger_l_joint7" class="finger_dip"/>
                                <geom type="mesh" mesh="hx5_l_finger_dip" material="black" class="visual"/>
                                <geom type="capsule" fromto="0 0 0.004255  0 0 0.034505" size="0.0105" class="hand_collision"/>
                                <body name="finger_l_link8" pos="0 0 0.0355">
                                  <inertial pos="0.000710251 0.000472384 0.0180986" mass="0.013637" diaginertia="2.23243e-06 2.01881e-06 1.07866e-06"/>
                                  <joint name="finger_l_joint8" class="finger_tip"/>
                                  <geom type="mesh" mesh="hx5_l_finger_tip" material="black" class="visual"/>
                                  <geom type="capsule" fromto="0.0015 0 0.006005  0.0015 0 0.025755" size="0.01225" class="hand_collision"/>
                                </body>
                              </body>
                            </body>
                          </body>

                          <!-- Middle finger (4 joints) -->
                          <body name="finger_l_link9" pos="-0.0015 -0.00908 0.10353">
                            <inertial pos="0.00519340 -1.81631e-05 0.0211155" mass="0.0388044" diaginertia="3.52499e-06 5.79216e-06 4.71268e-06"/>
                            <joint name="finger_l_joint9" class="finger_mcp"/>
                            <geom type="mesh" mesh="hx5_l_finger_mcp" material="black" class="visual"/>
                            <geom type="capsule" fromto="0.00685 0 0.00858  0.00685 0 0.01818" size="0.014825" class="hand_collision"/>
                            <body name="finger_l_link10" pos="0.0165 0 0.0235">
                              <inertial pos="4.08056e-06 0.000101462 0.0241565" mass="0.034690" diaginertia="5.40298e-06 5.03702e-06 2.25807e-06"/>
                              <joint name="finger_l_joint10" class="finger_pip"/>
                              <geom type="mesh" mesh="hx5_l_finger_pip" material="black" class="visual"/>
                              <geom type="capsule" fromto="0 0 0.004255  0 0 0.034505" size="0.0105" class="hand_collision"/>
                              <body name="finger_l_link11" pos="0 0 0.0355">
                                <inertial pos="4.08056e-06 0.000101462 0.0241565" mass="0.034690" diaginertia="5.40298e-06 5.03702e-06 2.25807e-06"/>
                                <joint name="finger_l_joint11" class="finger_dip"/>
                                <geom type="mesh" mesh="hx5_l_finger_dip" material="black" class="visual"/>
                                <geom type="capsule" fromto="0 0 0.004255  0 0 0.034505" size="0.0105" class="hand_collision"/>
                                <body name="finger_l_link12" pos="0 0 0.0355">
                                  <inertial pos="0.000710251 0.000472384 0.0180986" mass="0.013637" diaginertia="2.23243e-06 2.01881e-06 1.07866e-06"/>
                                  <joint name="finger_l_joint12" class="finger_tip"/>
                                  <geom type="mesh" mesh="hx5_l_finger_tip" material="black" class="visual"/>
                                  <geom type="capsule" fromto="0.0015 0 0.006005  0.0015 0 0.025755" size="0.01225" class="hand_collision"/>
                                </body>
                              </body>
                            </body>
                          </body>

                          <!-- Ring finger (4 joints) -->
                          <body name="finger_l_link13" pos="-0.0015 0.01792 0.09775">
                            <inertial pos="0.00519340 -1.81631e-05 0.0211155" mass="0.0388044" diaginertia="3.52499e-06 5.79216e-06 4.71268e-06"/>
                            <joint name="finger_l_joint13" class="finger_mcp" range="-0.0001 0.0001" limited="true"/>
                            <geom type="mesh" mesh="hx5_l_finger_mcp" material="black" class="visual"/>
                            <geom type="capsule" fromto="0.00685 0 0.00858  0.00685 0 0.01818" size="0.014825" class="hand_collision"/>
                            <body name="finger_l_link14" pos="0.0165 0 0.0235">
                              <inertial pos="4.08056e-06 0.000101462 0.0241565" mass="0.034690" diaginertia="5.40298e-06 5.03702e-06 2.25807e-06"/>
                              <joint name="finger_l_joint14" class="finger_pip"/>
                              <geom type="mesh" mesh="hx5_l_finger_pip" material="black" class="visual"/>
                              <geom type="capsule" fromto="0 0 0.004255  0 0 0.034505" size="0.0105" class="hand_collision"/>
                              <body name="finger_l_link15" pos="0 0 0.0355">
                                <inertial pos="4.08056e-06 0.000101462 0.0241565" mass="0.034690" diaginertia="5.40298e-06 5.03702e-06 2.25807e-06"/>
                                <joint name="finger_l_joint15" class="finger_dip"/>
                                <geom type="mesh" mesh="hx5_l_finger_dip" material="black" class="visual"/>
                                <geom type="capsule" fromto="0 0 0.004255  0 0 0.034505" size="0.0105" class="hand_collision"/>
                                <body name="finger_l_link16" pos="0 0 0.0355">
                                  <inertial pos="0.000710251 0.000472384 0.0180986" mass="0.013637" diaginertia="2.23243e-06 2.01881e-06 1.07866e-06"/>
                                  <joint name="finger_l_joint16" class="finger_tip"/>
                                  <geom type="mesh" mesh="hx5_l_finger_tip" material="black" class="visual"/>
                                  <geom type="capsule" fromto="0.0015 0 0.006005  0.0015 0 0.025755" size="0.01225" class="hand_collision"/>
                                </body>
                              </body>
                            </body>
                          </body>

                          <!-- Pinky finger (4 joints) -->
                          <body name="finger_l_link17" pos="-0.0015 0.04492 0.07875">
                            <inertial pos="0.00519340 -1.81631e-05 0.0211155" mass="0.0388044" diaginertia="3.52499e-06 5.79216e-06 4.71268e-06"/>
                            <joint name="finger_l_joint17" class="finger_mcp" range="-0.0001 0.0001" limited="true"/>
                            <geom type="mesh" mesh="hx5_l_finger_mcp" material="black" class="visual"/>
                            <geom type="capsule" fromto="0.00685 0 0.00858  0.00685 0 0.01818" size="0.014825" class="hand_collision"/>
                            <body name="finger_l_link18" pos="0.0165 0 0.0235">
                              <inertial pos="4.08056e-06 0.000101462 0.0241565" mass="0.034690" diaginertia="5.40298e-06 5.03702e-06 2.25807e-06"/>
                              <joint name="finger_l_joint18" class="finger_pip"/>
                              <geom type="mesh" mesh="hx5_l_finger_pip" material="black" class="visual"/>
                              <geom type="capsule" fromto="0 0 0.004255  0 0 0.034505" size="0.0105" class="hand_collision"/>
                              <body name="finger_l_link19" pos="0 0 0.0355">
                                <inertial pos="4.08056e-06 0.000101462 0.0241565" mass="0.034690" diaginertia="5.40298e-06 5.03702e-06 2.25807e-06"/>
                                <joint name="finger_l_joint19" class="finger_dip"/>
                                <geom type="mesh" mesh="hx5_l_finger_dip" material="black" class="visual"/>
                                <geom type="capsule" fromto="0 0 0.004255  0 0 0.034505" size="0.0105" class="hand_collision"/>
                                <body name="finger_l_link20" pos="0 0 0.0355">
                                  <inertial pos="0.000710251 0.000472384 0.0180986" mass="0.013637" diaginertia="2.23243e-06 2.01881e-06 1.07866e-06"/>
                                  <joint name="finger_l_joint20" class="finger_tip"/>
                                  <geom type="mesh" mesh="hx5_l_finger_tip" material="black" class="visual"/>
                                  <geom type="capsule" fromto="0.0015 0 0.006005  0.0015 0 0.025755" size="0.01225" class="hand_collision"/>
                                </body>
                              </body>
                            </body>
                          </body>
                        </body>
                      </body>
                    </body>
                  </body>
                </body>
              </body>
            </body>
          </body>

          <!-- Right arm -->
          <body name="arm_r_link1" pos="0 -0.1045 0">
            <inertial pos="0.0162454 -0.115083 -0.000116015" quat="0.212043 0.665609 -0.229062 0.677889" mass="1.93395" diaginertia="0.00305635 0.00275332 0.00221466"/>
            <joint name="arm_r_joint1" class="arm_r_joint1"/>
            <geom type="mesh" mesh="arm_r_link1" material="black" class="visual"/>
            <geom type="mesh" mesh="arm_r_link1" class="collision"/>

            <body name="arm_r_link2" pos="0 -0.123 0">
              <inertial pos="0.00904096 0.000105802 -0.144033" quat="0.707129 0.105833 0.108702 0.690617" mass="2.12414" diaginertia="0.0108559 0.0106863 0.00242145"/>
              <joint name="arm_r_joint2" class="arm_r_joint2"/>
              <geom type="mesh" mesh="arm_r_link2" material="black" class="visual"/>
              <geom type="mesh" mesh="arm_r_link2" class="collision"/>

              <body name="arm_r_link3" pos="0 0 -0.165">
                <inertial pos="-2.51092e-05 -0.0179472 -0.108765" quat="0.447823 0.894113 0.00400928 -0.000680335" mass="1.40774" diaginertia="0.00193273 0.0017314 0.00128994"/>
                <joint name="arm_r_joint3" class="arm_r_joint3"/>
                <geom type="mesh" mesh="arm_r_link3" material="black" class="visual"/>
                <geom type="mesh" mesh="arm_r_link3" class="collision"/>

                <body name="arm_r_link4" pos="0.041004 0 -0.135">
                  <inertial pos="4.39703e-05 -0.00978736 -0.137888" quat="0.984402 0.175809 0.00125565 -0.00649329" mass="1.51314" diaginertia="0.00636295 0.00628021 0.00133398"/>
                  <joint name="arm_r_joint4" class="arm_r_joint4"/>
                  <geom type="mesh" mesh="arm_r_link4" material="black" class="visual"/>
                  <geom type="mesh" mesh="arm_r_link4" class="collision"/>

                  <body name="arm_r_link5" pos="-0.041004 0 -0.1489">
                    <inertial pos="-2.62962e-05 -0.0187957 -0.0983871" quat="0.546043 0.837751 0.00318354 -0.000761107" mass="1.34419" diaginertia="0.00169762 0.00156986 0.00116911"/>
                    <joint name="arm_r_joint5" class="arm_r_joint5"/>
                    <geom type="mesh" mesh="arm_r_link5" material="black" class="visual"/>
                    <geom type="mesh" mesh="arm_r_link5" class="collision"/>

                    <body name="arm_r_link6" pos="0 0 -0.1041">
                      <inertial pos="0.000339839 -0.0194304 -0.0639459" quat="0.662489 0.249825 -0.2542 0.658846" mass="0.636234" diaginertia="0.00155564 0.00138901 0.000496769"/>
                      <joint name="arm_r_joint6" class="arm_r_joint6"/>
                      <geom type="mesh" mesh="arm_r_link6" material="black" class="visual"/>
                      <geom type="mesh" mesh="arm_r_link6" class="collision"/>

                      <body name="arm_r_link7" pos="0 0 -0.0885">
                        <inertial pos="-0.00242011 -0.00201564 -0.0911446" quat="0.703942 -0.0528198 -0.0236914 0.707894" mass="0.384359" diaginertia="0.00125471 0.0011001 0.000310982"/>
                        <joint name="arm_r_joint7" class="arm_r_joint7"/>
                        <geom type="mesh" mesh="arm_r_link7" material="black" class="visual"/>
                        <geom type="mesh" mesh="arm_r_link7" class="collision"/>
                        <geom size="0.0115 0.021 0.021" pos="0.107944 0 -0.065588" quat="0.475435 -0.475435 0.523413 0.523413" type="box"/>

                        <!-- Right hand (HX5-D20) -->
                        <body name="hx5_r_base" pos="0 0 -0.078" quat="0 0.7071068 0.7071068 0">
                          <inertial pos="-0.00259546 0.00179263 0.0629577" mass="0.301852" diaginertia="0.000542413 0.000389333 0.000210116"/>
                          <geom type="mesh" mesh="hx5_r_base" material="black" class="visual"/>
                          <geom name="palm_r_collision" type="box" size="0.02421 0.05536 0.06126" pos="-0.00321 -0.00121 0.06126" class="hand_collision"/>
                          <site name="grasp_target_r" pos="0.065 0.01 0.105" size="0.006" rgba="0 1 0 1"/>

                          <!-- Thumb (4 joints) -->
                          <body name="finger_r_link1" pos="-0.0125 0.03493 0.04475">
                            <inertial pos="0.0238075 0.00131524 0.000460355" mass="0.0408685" diaginertia="2.88193e-06 9.43334e-06 9.65126e-06"/>
                            <joint name="finger_r_joint1" class="thumb_r_cmc"/>
                            <geom type="mesh" mesh="hx5_r_thumb_mcp" material="black" class="visual"/>
                            <geom type="capsule" fromto="-0.000125 0.00225 0  0.037125 0.00225 0" size="0.011375" class="hand_collision"/>
                            <body name="finger_r_link2" pos="0.039 0 0">
                              <inertial pos="-0.000356679 0.0139993 0.000359207" mass="0.0117606" diaginertia="1.30235e-06 1.05564e-06 1.30247e-06"/>
                              <joint name="finger_r_joint2" class="thumb_r_mcp_yaw"/>
                              <geom type="mesh" mesh="hx5_r_thumb_mcp2" material="black" class="visual"/>
                              <geom type="capsule" fromto="0 0.00525 0  0 0.02275 0" size="0.0115" class="hand_collision"/>
                              <body name="finger_r_link3" pos="0 0.028 0">
                                <inertial pos="-0.000101462 0.0113435 4.08056e-06" mass="0.034690" diaginertia="5.03702e-06 2.25807e-06 5.40298e-06"/>
                                <joint name="finger_r_joint3" class="thumb_r_mcp_pitch"/>
                                <geom type="mesh" mesh="hx5_r_thumb_ip" material="black" class="visual"/>
                                <geom type="capsule" fromto="0 0.001 0  0 0.03125 0" size="0.0105" class="hand_collision"/>
                                <body name="finger_r_link4" pos="0 0.0355 0">
                                  <inertial pos="6.66050e-05 0.0168245 0.000223985" mass="0.043875" diaginertia="1.11607e-05 2.80794e-06 1.13431e-05"/>
                                  <joint name="finger_r_joint4" class="thumb_r_ip"/>
                                  <geom type="mesh" mesh="hx5_r_thumb_tip" material="black" class="visual"/>
                                  <geom type="capsule" fromto="0 0.0025 0.0015  0 0.0415 0.0015" size="0.012" class="hand_collision"/>
                                </body>
                              </body>
                            </body>
                          </body>

                          <!-- Index finger (4 joints) -->
                          <body name="finger_r_link5" pos="-0.0015 0.03608 0.09575">
                            <inertial pos="0.00519340 -1.81631e-05 0.0211155" mass="0.0388044" diaginertia="3.52499e-06 5.79216e-06 4.71268e-06"/>
                            <joint name="finger_r_joint5" class="finger_mcp"/>
                            <geom type="mesh" mesh="hx5_r_finger_mcp" material="black" class="visual"/>
                            <geom type="capsule" fromto="0.00685 0 0.00858  0.00685 0 0.01818" size="0.014825" class="hand_collision"/>
                            <body name="finger_r_link6" pos="0.0165 0 0.0235">
                              <inertial pos="4.08056e-06 0.000101462 0.0241565" mass="0.034690" diaginertia="5.40298e-06 5.03702e-06 2.25807e-06"/>
                              <joint name="finger_r_joint6" class="finger_pip"/>
                              <geom type="mesh" mesh="hx5_r_finger_pip" material="black" class="visual"/>
                              <geom type="capsule" fromto="0 0 0.004255  0 0 0.034505" size="0.0105" class="hand_collision"/>
                              <body name="finger_r_link7" pos="0 0 0.0355">
                                <inertial pos="4.08056e-06 0.000101462 0.0241565" mass="0.034690" diaginertia="5.40298e-06 5.03702e-06 2.25807e-06"/>
                                <joint name="finger_r_joint7" class="finger_dip"/>
                                <geom type="mesh" mesh="hx5_r_finger_dip" material="black" class="visual"/>
                                <geom type="capsule" fromto="0 0 0.004255  0 0 0.034505" size="0.0105" class="hand_collision"/>
                                <body name="finger_r_link8" pos="0 0 0.0355">
                                  <inertial pos="0.000710251 0.000472384 0.0180986" mass="0.013637" diaginertia="2.23243e-06 2.01881e-06 1.07866e-06"/>
                                  <joint name="finger_r_joint8" class="finger_tip"/>
                                  <geom type="mesh" mesh="hx5_r_finger_tip" material="black" class="visual"/>
                                  <geom type="capsule" fromto="0.0015 0 0.006005  0.0015 0 0.025755" size="0.01225" class="hand_collision"/>
                                </body>
                              </body>
                            </body>
                          </body>

                          <!-- Middle finger (4 joints) -->
                          <body name="finger_r_link9" pos="-0.0015 0.00908 0.10353">
                            <inertial pos="0.00519340 -1.81631e-05 0.0211155" mass="0.0388044" diaginertia="3.52499e-06 5.79216e-06 4.71268e-06"/>
                            <joint name="finger_r_joint9" class="finger_mcp"/>
                            <geom type="mesh" mesh="hx5_r_finger_mcp" material="black" class="visual"/>
                            <geom type="capsule" fromto="0.00685 0 0.00858  0.00685 0 0.01818" size="0.014825" class="hand_collision"/>
                            <body name="finger_r_link10" pos="0.0165 0 0.0235">
                              <inertial pos="4.08056e-06 0.000101462 0.0241565" mass="0.034690" diaginertia="5.40298e-06 5.03702e-06 2.25807e-06"/>
                              <joint name="finger_r_joint10" class="finger_pip"/>
                              <geom type="mesh" mesh="hx5_r_finger_pip" material="black" class="visual"/>
                              <geom type="capsule" fromto="0 0 0.004255  0 0 0.034505" size="0.0105" class="hand_collision"/>
                              <body name="finger_r_link11" pos="0 0 0.0355">
                                <inertial pos="4.08056e-06 0.000101462 0.0241565" mass="0.034690" diaginertia="5.40298e-06 5.03702e-06 2.25807e-06"/>
                                <joint name="finger_r_joint11" class="finger_dip"/>
                                <geom type="mesh" mesh="hx5_r_finger_dip" material="black" class="visual"/>
                                <geom type="capsule" fromto="0 0 0.004255  0 0 0.034505" size="0.0105" class="hand_collision"/>
                                <body name="finger_r_link12" pos="0 0 0.0355">
                                  <inertial pos="0.000710251 0.000472384 0.0180986" mass="0.013637" diaginertia="2.23243e-06 2.01881e-06 1.07866e-06"/>
                                  <joint name="finger_r_joint12" class="finger_tip"/>
                                  <geom type="mesh" mesh="hx5_r_finger_tip" material="black" class="visual"/>
                                  <geom type="capsule" fromto="0.0015 0 0.006005  0.0015 0 0.025755" size="0.01225" class="hand_collision"/>
                                </body>
                              </body>
                            </body>
                          </body>

                          <!-- Ring finger (4 joints) -->
                          <body name="finger_r_link13" pos="-0.0015 -0.01792 0.09775">
                            <inertial pos="0.00519340 -1.81631e-05 0.0211155" mass="0.0388044" diaginertia="3.52499e-06 5.79216e-06 4.71268e-06"/>
                            <joint name="finger_r_joint13" class="finger_mcp" range="-0.0001 0.0001" limited="true"/>
                            <geom type="mesh" mesh="hx5_r_finger_mcp" material="black" class="visual"/>
                            <geom type="capsule" fromto="0.00685 0 0.00858  0.00685 0 0.01818" size="0.014825" class="hand_collision"/>
                            <body name="finger_r_link14" pos="0.0165 0 0.0235">
                              <inertial pos="4.08056e-06 0.000101462 0.0241565" mass="0.034690" diaginertia="5.40298e-06 5.03702e-06 2.25807e-06"/>
                              <joint name="finger_r_joint14" class="finger_pip"/>
                              <geom type="mesh" mesh="hx5_r_finger_pip" material="black" class="visual"/>
                              <geom type="capsule" fromto="0 0 0.004255  0 0 0.034505" size="0.0105" class="hand_collision"/>
                              <body name="finger_r_link15" pos="0 0 0.0355">
                                <inertial pos="4.08056e-06 0.000101462 0.0241565" mass="0.034690" diaginertia="5.40298e-06 5.03702e-06 2.25807e-06"/>
                                <joint name="finger_r_joint15" class="finger_dip"/>
                                <geom type="mesh" mesh="hx5_r_finger_dip" material="black" class="visual"/>
                                <geom type="capsule" fromto="0 0 0.004255  0 0 0.034505" size="0.0105" class="hand_collision"/>
                                <body name="finger_r_link16" pos="0 0 0.0355">
                                  <inertial pos="0.000710251 0.000472384 0.0180986" mass="0.013637" diaginertia="2.23243e-06 2.01881e-06 1.07866e-06"/>
                                  <joint name="finger_r_joint16" class="finger_tip"/>
                                  <geom type="mesh" mesh="hx5_r_finger_tip" material="black" class="visual"/>
                                  <geom type="capsule" fromto="0.0015 0 0.006005  0.0015 0 0.025755" size="0.01225" class="hand_collision"/>
                                </body>
                              </body>
                            </body>
                          </body>

                          <!-- Pinky finger (4 joints) -->
                          <body name="finger_r_link17" pos="-0.0015 -0.04492 0.07875">
                            <inertial pos="0.00519340 -1.81631e-05 0.0211155" mass="0.0388044" diaginertia="3.52499e-06 5.79216e-06 4.71268e-06"/>
                            <joint name="finger_r_joint17" class="finger_mcp" range="-0.0001 0.0001" limited="true"/>
                            <geom type="mesh" mesh="hx5_r_finger_mcp" material="black" class="visual"/>
                            <geom type="capsule" fromto="0.00685 0 0.00858  0.00685 0 0.01818" size="0.014825" class="hand_collision"/>
                            <body name="finger_r_link18" pos="0.0165 0 0.0235">
                              <inertial pos="4.08056e-06 0.000101462 0.0241565" mass="0.034690" diaginertia="5.40298e-06 5.03702e-06 2.25807e-06"/>
                              <joint name="finger_r_joint18" class="finger_pip"/>
                              <geom type="mesh" mesh="hx5_r_finger_pip" material="black" class="visual"/>
                              <geom type="capsule" fromto="0 0 0.004255  0 0 0.034505" size="0.0105" class="hand_collision"/>
                              <body name="finger_r_link19" pos="0 0 0.0355">
                                <inertial pos="4.08056e-06 0.000101462 0.0241565" mass="0.034690" diaginertia="5.40298e-06 5.03702e-06 2.25807e-06"/>
                                <joint name="finger_r_joint19" class="finger_dip"/>
                                <geom type="mesh" mesh="hx5_r_finger_dip" material="black" class="visual"/>
                                <geom type="capsule" fromto="0 0 0.004255  0 0 0.034505" size="0.0105" class="hand_collision"/>
                                <body name="finger_r_link20" pos="0 0 0.0355">
                                  <inertial pos="0.000710251 0.000472384 0.0180986" mass="0.013637" diaginertia="2.23243e-06 2.01881e-06 1.07866e-06"/>
                                  <joint name="finger_r_joint20" class="finger_tip"/>
                                  <geom type="mesh" mesh="hx5_r_finger_tip" material="black" class="visual"/>
                                  <geom type="capsule" fromto="0.0015 0 0.006005  0.0015 0 0.025755" size="0.01225" class="hand_collision"/>
                                </body>
                              </body>
                            </body>
                          </body>
                        </body>
                      </body>
                    </body>
                  </body>
                </body>
              </body>
            </body>
          </body>
        </body>
      </body>
    </body>
  
    <!-- Table + can: same relative geometry validated in Phase 1-3 (models/arm_hand.xml),
         translated by the offset between arm_hand.xml's fixed arm_base (0,0,1.0) and this
         scene's arm_base_link resting position with lift_joint at its "home" value -0.5
         ((0.0055, 0, 1.0816), see NOTES.md "Phase 4") -- so grasp_target's local offset,
         the thumb pre-shape, HOME_Q and every capsule number above carry over unchanged. -->
    <!-- Footprint enlarged (Session 8 후속, user request) from 0.08x0.15 -- height/position
         unchanged (table top stays at exactly the same world z the can/grasp geometry was
         validated against), only made to look more like an actual table. -->
    <geom name="table" type="box" size="0.16 0.25 0.05" pos="0.5055 0.0 0.6816" material="table_mat"/>
    <body name="can" pos="0.5055 0.0 0.7866">
      <freejoint name="can_free"/>
      <inertial pos="0 0 0" mass="0.35" diaginertia="0.000448 0.000448 0.00019"/>
      <!-- Real detailed-mesh visual, split into the labeled side + plain aluminum caps
           (Session 8 후속 10, see <asset> comment for how these two meshes were derived
           from the same soda_can.stl) -- two geoms sharing the STL's original vertex
           positions exactly, so they join with no gap/seam, at no explicit pos/quat (same
           convention the original single-mesh soda_can visual used: raw mesh-local
           coordinates, scaled 1.1/1.1/0.7333 in <asset> to match can_geom below). -->
      <geom type="mesh" mesh="can_side_detail" material="can_mat" class="visual"/>
      <geom type="mesh" mesh="can_cap_detail" material="can_cap_mat" class="visual"/>
      <geom name="can_geom" type="cylinder" size="0.033 0.055" rgba="0 0 0 0"
        priority="1" condim="6" friction="0.5 0.01 0.003"
        solimp="0.5 0.99 0.0001" solref="0.005 1"/>
    </body>
    <body name="box_body" pos="0.5055 0.0 0.9316">
      <freejoint name="box_free"/>
      <geom name="box_geom" type="box" size="0.15 0.15 0.20" mass="0.3"
        rgba="0.8 0.6 0.3 1" priority="1" condim="6" friction="1.0 0.5 0.01"
        solimp="0.5 0.99 0.0001" solref="0.005 1"/>
    </body>
  </worldbody>

  <contact>

    <exclude body1="head_link1" body2="head_link2"/>
    <exclude body1="arm_base_link" body2="head_link1"/>
    <exclude body1="arm_base_link" body2="head_link2"/>
    <exclude body1="base_link" body2="left_wheel_steer"/>
    <exclude body1="base_link" body2="right_wheel_steer"/>
    <exclude body1="base_link" body2="rear_wheel_steer"/>
    <exclude body1="base_link" body2="lift_link"/>
    <exclude body1="lift_link" body2="arm_base_link"/>
    <exclude body1="arm_base_link" body2="arm_l_link1"/>
    <exclude body1="arm_base_link" body2="arm_r_link1"/>
    <!-- Left hand -->
    <exclude body1="arm_l_link7" body2="hx5_l_base"/>
    <exclude body1="hx5_l_base" body2="finger_l_link1"/>
    <exclude body1="hx5_l_base" body2="finger_l_link2"/>
    <exclude body1="finger_l_link1" body2="finger_l_link2"/>
    <exclude body1="finger_l_link2" body2="finger_l_link3"/>
    <exclude body1="finger_l_link3" body2="finger_l_link4"/>
    <exclude body1="hx5_l_base" body2="finger_l_link5"/>
    <exclude body1="hx5_l_base" body2="finger_l_link6"/>
    <exclude body1="finger_l_link5" body2="finger_l_link6"/>
    <exclude body1="finger_l_link6" body2="finger_l_link7"/>
    <exclude body1="finger_l_link7" body2="finger_l_link8"/>
    <exclude body1="hx5_l_base" body2="finger_l_link9"/>
    <exclude body1="hx5_l_base" body2="finger_l_link10"/>
    <exclude body1="finger_l_link9" body2="finger_l_link10"/>
    <exclude body1="finger_l_link10" body2="finger_l_link11"/>
    <exclude body1="finger_l_link11" body2="finger_l_link12"/>
    <exclude body1="hx5_l_base" body2="finger_l_link13"/>
    <exclude body1="hx5_l_base" body2="finger_l_link14"/>
    <exclude body1="finger_l_link13" body2="finger_l_link14"/>
    <exclude body1="finger_l_link14" body2="finger_l_link15"/>
    <exclude body1="finger_l_link15" body2="finger_l_link16"/>
    <exclude body1="hx5_l_base" body2="finger_l_link17"/>
    <exclude body1="hx5_l_base" body2="finger_l_link18"/>
    <exclude body1="finger_l_link17" body2="finger_l_link18"/>
    <exclude body1="finger_l_link18" body2="finger_l_link19"/>
    <exclude body1="finger_l_link19" body2="finger_l_link20"/>
    <!-- Right hand -->
    <exclude body1="arm_r_link7" body2="hx5_r_base"/>
    <exclude body1="hx5_r_base" body2="finger_r_link1"/>
    <exclude body1="hx5_r_base" body2="finger_r_link2"/>
    <exclude body1="finger_r_link1" body2="finger_r_link2"/>
    <exclude body1="finger_r_link2" body2="finger_r_link3"/>
    <exclude body1="finger_r_link3" body2="finger_r_link4"/>
    <exclude body1="hx5_r_base" body2="finger_r_link5"/>
    <exclude body1="hx5_r_base" body2="finger_r_link6"/>
    <exclude body1="finger_r_link5" body2="finger_r_link6"/>
    <exclude body1="finger_r_link6" body2="finger_r_link7"/>
    <exclude body1="finger_r_link7" body2="finger_r_link8"/>
    <exclude body1="hx5_r_base" body2="finger_r_link9"/>
    <exclude body1="hx5_r_base" body2="finger_r_link10"/>
    <exclude body1="finger_r_link9" body2="finger_r_link10"/>
    <exclude body1="finger_r_link10" body2="finger_r_link11"/>
    <exclude body1="finger_r_link11" body2="finger_r_link12"/>
    <exclude body1="hx5_r_base" body2="finger_r_link13"/>
    <exclude body1="hx5_r_base" body2="finger_r_link14"/>
    <exclude body1="finger_r_link13" body2="finger_r_link14"/>
    <exclude body1="finger_r_link14" body2="finger_r_link15"/>
    <exclude body1="finger_r_link15" body2="finger_r_link16"/>
    <exclude body1="hx5_r_base" body2="finger_r_link17"/>
    <exclude body1="hx5_r_base" body2="finger_r_link18"/>
    <exclude body1="finger_r_link17" body2="finger_r_link18"/>
    <exclude body1="finger_r_link18" body2="finger_r_link19"/>
    <exclude body1="finger_r_link19" body2="finger_r_link20"/>
  
    <!-- Cross-finger MCP excludes (capsule approximation is fatter than the mesh, phase 2 finding) -->
    <exclude body1="finger_l_link5" body2="finger_l_link9"/>
    <exclude body1="finger_l_link9" body2="finger_l_link13"/>
    <exclude body1="finger_l_link13" body2="finger_l_link17"/>
    <exclude body1="finger_r_link5" body2="finger_r_link9"/>
    <exclude body1="finger_r_link9" body2="finger_r_link13"/>
    <exclude body1="finger_r_link13" body2="finger_r_link17"/>
    <!-- Palm collision box is the real base_unit mesh's own tight AABB (verified against
         trimesh -- not a padded approximation), but the mesh isn't box-shaped, so the box
         claims corner volume the real curved/tapered hand never occupies. The validated
         pick pose points this box at the can's center from above-and-behind, which puts its
         far corner *kinematically* ~11-12mm below the table top if IK is solved with no
         collision at all (measured directly: see NOTES.md "Phase 4 Session 8"). A blanket
         <exclude> against world (this repo's earlier fix, and arm_hand.xml's Phase 3
         approach) hides this by removing ALL force, including a genuine deep push -- which is
         exactly the "hand goes through the table" bug reported during manual teleop.
         Fix: a per-pair solimp ramp, soft near dist=0 and reaching normal stiffness by
         `width`. Because the arm is a stiff PD+gravity-feedforward torque controller
         (src/arm_control.py, kp=600) rather than a compliant one, it pushes straight through
         any resistance well short of a spring's nominal free length -- measured settled
         penetration plateaus at only ~3-6mm even for width up to 30mm, nowhere near the
         "no collision at all" 11-12mm figure. width=15mm was the smallest tested value that
         reliably reproduces tests/test_phase_4.py's validated pick geometry (10/10, confirmed
         across the full trial set, not just the trials that previously failed), while still
         ramping to near-default stiffness for any push beyond that (so a deliberate manual
         push settles a few mm in, not through the table -- see diag script in NOTES.md). -->
    <pair geom1="palm_l_collision" geom2="table" solref="0.005 1" solimp="0.0001 0.95 0.015"/>
    <pair geom1="palm_r_collision" geom2="table" solref="0.005 1" solimp="0.0001 0.95 0.015"/>
    <pair geom1="palm_l_collision" geom2="floor" solref="0.005 1" solimp="0.0001 0.95 0.015"/>
    <pair geom1="palm_r_collision" geom2="floor" solref="0.005 1" solimp="0.0001 0.95 0.015"/>
    <!-- Wheel-floor contact (Session 8 후속 6, retuned 후속 8): base_link only has
         base_x/base_y/base_yaw joints (Phase 4's deliberate simplification, no vertical or
         tilt DOF -- see the wheel bodies' comment above), so the wheels' ~1.5mm floor
         overlap (itself deliberate, see NOTES.md "Phase 5 후속 2" on numerically-unstable
         exact-zero gaps) can never settle to a natural equilibrium depth the way it would
         on a body that's actually free to sink under load -- there's no DOF for it to sink
         into. With MuJoCo's default solref (0.02 1) at that fixed, unrelaxable 1.5mm depth,
         the resulting restoring force measured ~27,500N total across the 3 wheels (2
         contact points each) -- 28x the robot's actual 982N weight. That artificial
         over-stiffness doesn't blow up (nothing to run away into) but makes every wheel
         behave as if pinned into the ground far harder than its real load, which is why
         steering felt sluggish (pivoting a wheel scrubbing against that much phantom normal
         force needed far more torque than a realistically-loaded wheel would) and in-place
         rotation barely happened at all. solref="0.15 1" (retuned from the first pass's
         "0.1 1" -- see NOTES.md "Phase 5 후속 8") plus wheel_drive's kv=150 (below,
         retuned from 30) together were the best swept combination: steering aligns in
         ~0.5s (vs ~5s unfixed), steady in-place yaw rate reaches ~23% of the commanded
         rate (vs ~0.5% unfixed) with the lowest peak transient among combinations tried,
         and straight-line driving actually improves slightly (0.46->0.49 m/s, same 0.8%
         slip) as a side effect of the higher kv. Idle drift is byte-for-byte unchanged
         (0.645mm) since neither knob does anything without a drive command. Rotation is
         still well under the commanded 1.2 rad/s -- a further, deeper traction ceiling
         this combination doesn't fully remove, see NOTES.md for the fuller sweep data. -->
    <pair geom1="left_wheel_collision" geom2="floor" solref="0.15 1"/>
    <pair geom1="right_wheel_collision" geom2="floor" solref="0.15 1"/>
    <pair geom1="rear_wheel_collision" geom2="floor" solref="0.15 1"/>
    <!-- Ring/pinky locked at range=0 (3-point grasp fallback, Phase 2); excluded vs world same as palm -->
    <exclude body1="finger_l_link13" body2="world"/>
    <exclude body1="finger_l_link14" body2="world"/>
    <exclude body1="finger_l_link15" body2="world"/>
    <exclude body1="finger_l_link16" body2="world"/>
    <exclude body1="finger_l_link17" body2="world"/>
    <exclude body1="finger_l_link18" body2="world"/>
    <exclude body1="finger_l_link19" body2="world"/>
    <exclude body1="finger_l_link20" body2="world"/>
    <exclude body1="finger_r_link13" body2="world"/>
    <exclude body1="finger_r_link14" body2="world"/>
    <exclude body1="finger_r_link15" body2="world"/>
    <exclude body1="finger_r_link16" body2="world"/>
    <exclude body1="finger_r_link17" body2="world"/>
    <exclude body1="finger_r_link18" body2="world"/>
    <exclude body1="finger_r_link19" body2="world"/>
    <exclude body1="finger_r_link20" body2="world"/>
  </contact>

  <actuator>

    <!-- Mobile base (Session 8 후속): base_x/base_y/base_yaw joints are no longer directly
         actuated -- they're still there (base_link stays planar-constrained, no tipping)
         but now only move in reaction to real wheel-ground friction, via the wheel
         steer/drive actuators below. See src/base_teleop.py for the swerve-style per-wheel
         steer angle + drive speed conversion from a desired body-frame velocity. -->
    <position class="left_wheel_steer" name="left_wheel_steer" joint="left_wheel_steer_joint" inheritrange="1"/>
    <position class="right_wheel_steer" name="right_wheel_steer" joint="right_wheel_steer_joint" inheritrange="1"/>
    <position class="rear_wheel_steer" name="rear_wheel_steer" joint="rear_wheel_steer_joint" inheritrange="1"/>
    <velocity class="wheel_drive" name="left_wheel_drive" joint="left_wheel_drive_joint"/>
    <velocity class="wheel_drive" name="right_wheel_drive" joint="right_wheel_drive_joint"/>
    <velocity class="wheel_drive" name="rear_wheel_drive" joint="rear_wheel_drive_joint"/>
    <!-- Slider -->
    <position class="lift_joint" name="lift_joint" joint="lift_joint" inheritrange="1"/>
    <!-- Head -->
    <position class="head_joint1" name="head_joint1" joint="head_joint1" inheritrange="1"/>
    <position class="head_joint2" name="head_joint2" joint="head_joint2" inheritrange="1"/>
    <!-- Left arm -->
    <motor name="arm_l_joint1" joint="arm_l_joint1" ctrlrange="-61.4 61.4"/>
    <motor name="arm_l_joint2" joint="arm_l_joint2" ctrlrange="-61.4 61.4"/>
    <motor name="arm_l_joint3" joint="arm_l_joint3" ctrlrange="-31.7 31.7"/>
    <motor name="arm_l_joint4" joint="arm_l_joint4" ctrlrange="-31.7 31.7"/>
    <motor name="arm_l_joint5" joint="arm_l_joint5" ctrlrange="-31.7 31.7"/>
    <motor name="arm_l_joint6" joint="arm_l_joint6" ctrlrange="-31.7 31.7"/>
    <motor name="arm_l_joint7" joint="arm_l_joint7" ctrlrange="-5.1 5.1"/>
    <!-- Left hand fingers -->
    <position class="thumb_l_cmc" name="finger_l_joint1" joint="finger_l_joint1" inheritrange="1"/>
    <position class="thumb_l_mcp_yaw" name="finger_l_joint2" joint="finger_l_joint2" inheritrange="1"/>
    <position class="thumb_l_mcp_pitch" name="finger_l_joint3" joint="finger_l_joint3" inheritrange="1"/>
    <position class="thumb_l_ip" name="finger_l_joint4" joint="finger_l_joint4" inheritrange="1"/>
    <position class="finger_mcp" name="finger_l_joint5" joint="finger_l_joint5" inheritrange="1"/>
    <position class="finger_pip" name="finger_l_joint6" joint="finger_l_joint6" inheritrange="1"/>
    <position class="finger_dip" name="finger_l_joint7" joint="finger_l_joint7" inheritrange="1"/>
    <position class="finger_tip" name="finger_l_joint8" joint="finger_l_joint8" inheritrange="1"/>
    <position class="finger_mcp" name="finger_l_joint9" joint="finger_l_joint9" inheritrange="1"/>
    <position class="finger_pip" name="finger_l_joint10" joint="finger_l_joint10" inheritrange="1"/>
    <position class="finger_dip" name="finger_l_joint11" joint="finger_l_joint11" inheritrange="1"/>
    <position class="finger_tip" name="finger_l_joint12" joint="finger_l_joint12" inheritrange="1"/>
    <!-- Left ring/pinky (Session 8 후속): pip/dip/tip range widened from the Phase 2
         locked-at-0 fallback (see NOTES.md "Phase 5 후속") for a cosmetic curl driven by
         grasp.py's RING_PINKY_CURL_JOINTS mapping -- they still never touch the can (no
         actuator here overrides that, it's purely grasp.py's ctrl writes each step), this
         is visual only. mcp (spread) stays locked at 0/unactuated, same as Phase 2 --
         inheritrange can't attach to a zero-width range anyway (Session 2 finding), and no
         spread is wanted here regardless.
         grasp.py scales this curl by the live `grasp` scalar (0 at rest -> fully extended,
         capped at 35% of range at grasp=1.0), not a flat constant -- see NOTES.md "Phase 5
         후속 4" for why a flat 35%-regardless-of-grasp constant (Session 8 후속 3's original
         fix) was replaced: it left these two fingers visibly curled even at rest while every
         other digit starts fully open, which is wrong on its own terms regardless of how it
         looks mid-grasp. The keyframe below now leaves qpos/ctrl at 0 for these joints
         (matching grasp=0's fully-extended rest state) since grasp.py re-commands them every
         physics step from there. 35% remains the cap actually reached at grasp=1.0, same
         cliff-tested value as before (20-40% all held tests/test_phase_4.py's pick at 10/10,
         45%+ dropped to 0/10). -->
    <position class="finger_pip" name="finger_l_joint14" joint="finger_l_joint14" inheritrange="1"/>
    <position class="finger_dip" name="finger_l_joint15" joint="finger_l_joint15" inheritrange="1"/>
    <position class="finger_tip" name="finger_l_joint16" joint="finger_l_joint16" inheritrange="1"/>
    <position class="finger_pip" name="finger_l_joint18" joint="finger_l_joint18" inheritrange="1"/>
    <position class="finger_dip" name="finger_l_joint19" joint="finger_l_joint19" inheritrange="1"/>
    <position class="finger_tip" name="finger_l_joint20" joint="finger_l_joint20" inheritrange="1"/>
    <!-- Right arm -->
    <motor name="arm_r_joint1" joint="arm_r_joint1" ctrlrange="-61.4 61.4"/>
    <motor name="arm_r_joint2" joint="arm_r_joint2" ctrlrange="-61.4 61.4"/>
    <motor name="arm_r_joint3" joint="arm_r_joint3" ctrlrange="-31.7 31.7"/>
    <motor name="arm_r_joint4" joint="arm_r_joint4" ctrlrange="-31.7 31.7"/>
    <motor name="arm_r_joint5" joint="arm_r_joint5" ctrlrange="-31.7 31.7"/>
    <motor name="arm_r_joint6" joint="arm_r_joint6" ctrlrange="-31.7 31.7"/>
    <motor name="arm_r_joint7" joint="arm_r_joint7" ctrlrange="-5.1 5.1"/>
    <!-- Right hand fingers -->
    <position class="thumb_r_cmc" name="finger_r_joint1" joint="finger_r_joint1" inheritrange="1"/>
    <position class="thumb_r_mcp_yaw" name="finger_r_joint2" joint="finger_r_joint2" inheritrange="1"/>
    <position class="thumb_r_mcp_pitch" name="finger_r_joint3" joint="finger_r_joint3" inheritrange="1"/>
    <position class="thumb_r_ip" name="finger_r_joint4" joint="finger_r_joint4" inheritrange="1"/>
    <position class="finger_mcp" name="finger_r_joint5" joint="finger_r_joint5" inheritrange="1"/>
    <position class="finger_pip" name="finger_r_joint6" joint="finger_r_joint6" inheritrange="1"/>
    <position class="finger_dip" name="finger_r_joint7" joint="finger_r_joint7" inheritrange="1"/>
    <position class="finger_tip" name="finger_r_joint8" joint="finger_r_joint8" inheritrange="1"/>
    <position class="finger_mcp" name="finger_r_joint9" joint="finger_r_joint9" inheritrange="1"/>
    <position class="finger_pip" name="finger_r_joint10" joint="finger_r_joint10" inheritrange="1"/>
    <position class="finger_dip" name="finger_r_joint11" joint="finger_r_joint11" inheritrange="1"/>
    <position class="finger_tip" name="finger_r_joint12" joint="finger_r_joint12" inheritrange="1"/>
    <!-- Right ring/pinky (Session 8 후속, see left hand comment above) -->
    <position class="finger_pip" name="finger_r_joint14" joint="finger_r_joint14" inheritrange="1"/>
    <position class="finger_dip" name="finger_r_joint15" joint="finger_r_joint15" inheritrange="1"/>
    <position class="finger_tip" name="finger_r_joint16" joint="finger_r_joint16" inheritrange="1"/>
    <position class="finger_pip" name="finger_r_joint18" joint="finger_r_joint18" inheritrange="1"/>
    <position class="finger_dip" name="finger_r_joint19" joint="finger_r_joint19" inheritrange="1"/>
    <position class="finger_tip" name="finger_r_joint20" joint="finger_r_joint20" inheritrange="1"/>

  </actuator>

  <keyframe>
    <key name="home"
      qpos="0 0 0 0 0 0 0 0 0 -0.39 0 0 0 0 0 -1.570796 0 0 0 0.131 1.309 0 0 0 0 0 0 0 0 0 0 0 0 0 0 0 0 0 0 0 0 0 -1.570796 0 0 0 0.131 -1.309 0 0 0 0 0 0 0 0 0 0 0 0 0 0 0 0 0 0 0.5055 0 0.7866 1 0 0 0 2.0 2.0 0.348 1 0 0 0"
      ctrl="0 0 0 0 0 0 -0.39 0 0 0 0 0 0 0 0 0 0.131 1.309 0 0 0 0 0 0 0 0 0 0 0 0 0 0 0 0 0 0 0 0 0 0 0 0.131 -1.309 0 0 0 0 0 0 0 0 0 0 0 0 0 0 0 0"/>
  </keyframe>
</mujoco>
